Workbook

Sheet 総表
D3: 45870 | E3: 45901 | H3: 単位 | I3: 45931 | L3: 45962 | O3: 45992 | R3: 46023 | U3: 46054 | X3: 46082 | AA3: 46113 | AD3: 46143 | AG3: 46174 | AJ3: 46204 | AM3: 46235 | AP3: 46266 | AS3: 小計
D4: 2397538 | E4: 3476309 | F4: 1 | G4: 総売上 | H4: 円 | I4: ='2025年10月分析データ表'!C9 -> 6737353 | L4: ='2025年11月予約一覧表'!K2 -> 7079337 | O4: ='2025年12月分析データ表'!C9 -> 7256184 | R4: ='2026年1月分析データ表'!C9 -> 6715278 | U4: ='2026年２月分析データ表'!C9 -> 5113703 | X4: ='2026年3月分析データ表'!C9 -> 7046459 | AA4: ='2026年月4分析データ表'!C9 -> 9682526 | AS4: =SUM(I4:AR4) -> 49630840
G5: 目標 | H5: 円 | I5: 8311944 | L5: 6770995 | O5: 6450137 | R5: 7471898 | U5: 6679618 | X5: 7001514 | AA5: 9033013 | AD5: 6025818 | AG5: 6523843 | AJ5: 7984589 | AM5: 8250742 | AP5: 6677631 | AS5: =SUM(I5:AR5) -> 87181742
G6: 達成率 | H6: ％ | I6: =I4/I5*100% -> 0.81056285 | L6: =L4/L5*100% -> 1.0455387 | O6: =O4/O5*100% -> 1.1249659 | R6: =R4/R5*100% -> 0.89873791 | U6: =U4/U5*100% -> 0.76556818 | X6: =X4/X5*100% -> 1.0064193 | AA6: =AA4/AA5*100% -> 1.0719044
F7: 2 | G7: 総宿泊人数 | H7: 人 | I7: ='2025年10月分析データ表'!C10 -> 186 | L7: ='2025年11月分析データ表'!C10 -> 208 | O7: ='2025年12月分析データ表'!C10 -> 221 | R7: ='2026年1月分析データ表'!C10 -> 187 | U7: ='2026年２月分析データ表'!C10 -> 163 | X7: ='2026年3月分析データ表'!C10 -> 179 | AA7: 165 | AS7: =I7+L7+O7+R7+U7+X7+AA7+AD7+AG7+AJ7+AM7+AP7 -> 1309
F8: 3 | G8: 宿泊延べ日数 | H8: 人泊 | I8: ='2025年10月分析データ表'!C11 -> 609 | L8: ='2025年11月分析データ表'!C11 -> 634 | O8: ='2025年12月分析データ表'!C11 -> 654 | R8: ='2026年1月分析データ表'!C11 -> 635 | U8: ='2026年２月分析データ表'!C11 -> 559 | X8: ='2026年3月分析データ表'!C11 -> 680 | AA8: 648 | AS8: =I8+L8+O8+R8+U8+X8+AA8+AD8+AG8+AJ8+AM8+AP8 -> 4419
F9: 4 | G9: 販売可能室数 | H9: 室 | I9: ='2025年10月分析データ表'!C12 -> 9 | L9: ='2025年11月分析データ表'!C12 -> 9 | O9: ='2025年12月分析データ表'!C8 -> 9 | R9: ='2026年1月分析データ表'!C8 -> 9 | U9: ='2026年２月分析データ表'!C12 -> 9 | X9: ='2026年3月分析データ表'!C8 -> 9 | AA9: 9 | AS9: =I9+L9+O9+R9+U9+X9+AA9+AD9+AG9+AJ9+AM9+AP9 -> 63
F10: 5 | G10: 販売可能数 | H10: 室 | I10: ='2025年10月分析データ表'!C13 -> 279 | L10: ='2025年11月分析データ表'!C13 -> 270 | O10: ='2025年12月分析データ表'!C13 -> 279 | R10: ='2026年1月分析データ表'!C13 -> 279 | U10: ='2026年２月分析データ表'!C13 -> 252 | X10: ='2026年3月分析データ表'!C13 -> 279 | AA10: 270 | AS10: =I10+L10+O10+R10+U10+X10+AA10+AD10+AG10+AJ10+AM10+AP10 -> 1908
F11: 6 | G11: 販売可能室泊 | H11: 室泊 | I11: ='2025年10月分析データ表'!C13 -> 279 | L11: ='2025年11月分析データ表'!C13 -> 270 | O11: ='2025年12月分析データ表'!C13 -> 279 | R11: ='2026年1月分析データ表'!C13 -> 279 | U11: ='2026年２月分析データ表'!C13 -> 252 | X11: ='2026年3月分析データ表'!C13 -> 279 | AA11: 270 | AS11: =I11+L11+O11+R11+U11+X11+AA11+AD11+AG11+AJ11+AM11+AP11 -> 1908
F12: 7 | G12: 販売売室泊 | H12: 室泊 | I12: ='2025年10月分析データ表'!C14 -> 239 | L12: ='2025年11月分析データ表'!C14 -> 251 | O12: ='2025年12月分析データ表'!C14 -> 248 | R12: ='2026年1月分析データ表'!C14 -> 224 | U12: ='2026年２月分析データ表'!C14 -> 199 | X12: ='2026年3月分析データ表'!C14 -> 240 | AA12: 239 | AS12: =I12+L12+O12+R12+U12+X12+AA12+AD12+AG12+AJ12+AM12+AP12 -> 1640
F13: 8 | G13: 稼働率 | H13: ％ | I13: ='2025年10月分析データ表'!C23 -> 0.85663082 | L13: ='2025年11月分析データ表'!C23 -> 0.92962963 | O13: ='2025年12月分析データ表'!C23 -> 0.88888889 | R13: ='2026年1月分析データ表'!C23 -> 0.80286738 | U13: ='2026年２月分析データ表'!C23 -> 0.78968254 | X13: ='2026年3月分析データ表'!C23 -> 0.86021505 | AA13: 0.885 | AS13: =(I13+L13+O13+R13+U13+X13+AA13+AD13+AG13+AJ13+AM13+AP13)/12 -> 0.50107619
F14: 9 | G14: ADR | H14: 円 | I14: ='2025年10月分析データ表'!C24 -> 28189.762 | L14: ='2025年11月分析データ表'!C24 -> 28204.53 | O14: ='2025年12月分析データ表'!C24 -> 29258.806 | R14: ='2026年1月分析データ表'!C24 -> 29978.92 | U14: ='2026年２月分析データ表'!C24 -> 25697 | X14: ='2026年3月分析データ表'!C24 -> 29360.246 | AA14: 40513 | AS14: =(I14+L14+O14+R14+U14+X14+AA14+AD14+AG14+AJ14+AM14+AP14)/12 -> 17600.189
F15: 10 | G15: RevPAR | H15: 円 | I15: ='2025年10月分析データ表'!C26 -> 24148.219 | L15: ='2025年11月分析データ表'!C26 -> 26219.767 | O15: ='2025年12月分析データ表'!C26 -> 26007.828 | R15: ='2026年1月分析データ表'!C26 -> 24069.097 | U15: ='2026年２月分析データ表'!C26 -> 20292.472 | X15: ='2026年3月分析データ表'!C26 -> 25256.125 | AA15: 35861 | AS15: =(I15+L15+O15+R15+U15+X15+AA15+AD15+AG15+AJ15+AM15+AP15)/12 -> 15154.542
F16: 11 | G16: ㎡単価/日 | H16: 円 | I16: ='2025年10月分析データ表'!C27 -> 610.48867 | L16: ='2025年11月分析データ表'!C27 -> 662.85927 | O16: ='2025年12月分析データ表'!C27 -> 657.50127 | R16: ='2026年1月分析データ表'!C27 -> 608.4884 | U16: ='2026年２月分析データ表'!C27 -> 513.01194 | X16: ='2026年3月分析データ表'!C27 -> 638.49755 | AA16: 907 | AS16: =(I16+L16+O16+R16+U16+X16+AA16+AD16+AG16+AJ16+AM16+AP16)/12 -> 383.15393
F17: 12 | G17: 平均宿泊人数 | H17: 人数 | I17: =I7/J29 -> 2.5479452 | L17: =L7/M29 -> 2.5060241 | O17: =O7/P29 -> 2.6309524 | R17: =R7/S29 -> 2.75 | U17: =U7/V29 -> 2.9636364 | X17: =X7/Y29 -> 2.796875 | AA17: =AA7/AB29 -> 2.6612903 | AS17: =(I17+L17+O17+R17+U17+X17+AA17+AD17+AG17+AJ17+AM17+AP17)/12 -> 1.5713936
F18: 13 | G18: 平均宿泊日数 | H18: 日数 | I18: =I8/I12 -> 2.5481172 | L18: =L8/L12 -> 2.5258964 | O18: =O8/O12 -> 2.6370968 | R18: =R8/R12 -> 2.8348214 | U18: =U8/U12 -> 2.8090452 | X18: =X8/X12 -> 2.8333333 | AA18: =AA8/AA12 -> 2.7112971 | AS18: =(I18+L18+O18+R18+U18+X18+AA18+AD18+AG18+AJ18+AM18+AP18)/12 -> 1.5749673
G20: OTA別 | I20: ='2025年10月分析データ表'!F4 -> E（売上） | J20: ='2025年10月分析データ表'!G4 -> F（予約件数） | K20: ='2025年10月分析データ表'!H4 -> G（売上構成比） | L20: ='2025年11月分析データ表'!F4 -> E（売上） | M20: ='2025年11月分析データ表'!G4 -> F（予約件数） | N20: ='2025年11月分析データ表'!H4 -> G（売上構成比） | O20: ='2025年12月分析データ表'!F4 -> E（売上） | P20: ='2025年12月分析データ表'!G4 -> F（予約件数） | Q20: ='2025年12月分析データ表'!H4 -> G（売上構成比） | R20: ='2026年1月分析データ表'!F4 -> E（売上） | S20: ='2026年1月分析データ表'!G4 -> F（予約件数） | T20: ='2026年1月分析データ表'!H4 -> G（売上構成比） | U20: ='2026年２月分析データ表'!F4 -> E（売上） | V20: ='2026年２月分析データ表'!G4 -> F（予約件数） | W20: ='2026年２月分析データ表'!H4 -> G（売上構成比） | X20: ='2026年3月分析データ表'!F4 -> E（売上） | Y20: ='2026年3月分析データ表'!G4 -> F（予約件数） | Z20: ='2026年3月分析データ表'!H4 -> G（売上構成比） | AA20: E（売上） | AB20: F（予約件数） | AC20: G（売上構成比）
F21: 14 | G21: Airbnb | I21: ='2025年10月分析データ表'!F5 -> 1926460 | J21: ='2025年10月分析データ表'!G5 -> 19 | K21: ='2025年10月分析データ表'!H5 -> 0.28593722 | L21: ='2025年11月分析データ表'!F5 -> 1609290 | M21: ='2025年11月分析データ表'!G5 -> 15 | N21: ='2025年11月分析データ表'!H5 -> 0.22732213 | O21: ='2025年12月分析データ表'!F5 -> 1185190 | P21: ='2025年12月分析データ表'!G5 -> 14 | Q21: ='2025年12月分析データ表'!H5 -> 0.16333516 | R21: ='2026年1月分析データ表'!F5 -> 1254800 | S21: ='2026年1月分析データ表'!G5 -> 10 | T21: ='2026年1月分析データ表'!H5 -> 0.18685749 | U21: ='2026年２月分析データ表'!F5 -> 817650 | V21: ='2026年２月分析データ表'!G5 -> 8 | W21: ='2026年２月分析データ表'!H5 -> 0.15989392 | X21: ='2026年3月分析データ表'!F5 -> 1555150 | Y21: ='2026年3月分析データ表'!G5 -> 9 | Z21: ='2026年3月分析データ表'!H5 -> 0.2206995 | AA21: 457128 | AB21: 3 | AC21: 0.047
F22: 15 | G22: Booking.com | I22: ='2025年10月分析データ表'!F6 -> 1263819 | J22: ='2025年10月分析データ表'!G6 -> 10 | K22: ='2025年10月分析データ表'!H6 -> 0.18758391 | L22: ='2025年11月分析データ表'!F6 -> 1415977 | M22: ='2025年11月分析データ表'!G6 -> 20 | N22: ='2025年11月分析データ表'!H6 -> 0.20001548 | O22: ='2025年12月分析データ表'!F6 -> 1210694 | P22: ='2025年12月分析データ表'!G6 -> 14 | Q22: ='2025年12月分析データ表'!H6 -> 0.16684996 | R22: ='2026年1月分析データ表'!F6 -> 707056 | S22: ='2026年1月分析データ表'!G6 -> 10 | T22: ='2026年1月分析データ表'!H6 -> 0.10529065 | U22: ='2026年２月分析データ表'!F6 -> 1891784 | V22: ='2026年２月分析データ表'!G6 -> 17 | W22: ='2026年２月分析データ表'!H6 -> 0.36994405 | X22: ='2026年3月分析データ表'!F6 -> 4271321 | Y22: ='2026年3月分析データ表'!G6 -> 44 | Z22: ='2026年3月分析データ表'!H6 -> 0.60616559 | AA22: 7052658 | AB22: 47 | AC22: 0.728
F23: 16 | G23: Agoda | I23: ='2025年10月分析データ表'!F7 -> 1826777 | J23: ='2025年10月分析データ表'!G7 -> 22 | K23: ='2025年10月分析データ表'!H7 -> 0.27114165 | L23: ='2025年11月分析データ表'!F7 -> 1386279 | M23: ='2025年11月分析データ表'!G7 -> 18 | N23: ='2025年11月分析データ表'!H7 -> 0.19582046 | O23: ='2025年12月分析データ表'!F7 -> 2622268 | P23: ='2025年12月分析データ表'!G7 -> 23 | Q23: ='2025年12月分析データ表'!H7 -> 0.36138389 | R23: ='2026年1月分析データ表'!F7 -> 2614816 | S23: ='2026年1月分析データ表'!G7 -> 18 | T23: ='2026年1月分析データ表'!H7 -> 0.38938313 | U23: ='2026年２月分析データ表'!F7 -> 1213149 | V23: ='2026年２月分析データ表'!G7 -> 11 | W23: ='2026年２月分析データ表'!H7 -> 0.23723494 | X23: ='2026年3月分析データ表'!F7 -> 61506 | Y23: ='2026年3月分析データ表'!G7 -> 1 | Z23: ='2026年3月分析データ表'!H7 -> 0.0087286394 | AA23: 663830 | AB23: 3 | AC23: 0.069 | AD23: ·
F24: 17 | G24: Expedia | I24: ='2025年10月分析データ表'!F8 -> 234387 | J24: ='2025年10月分析データ表'!G8 -> 3 | K24: ='2025年10月分析データ表'!H8 -> 0.034789182 | L24: ='2025年11月分析データ表'!F8 -> 1364207 | M24: ='2025年11月分析データ表'!G8 -> 8 | N24: ='2025年11月分析データ表'!H8 -> 0.19270265 | O24: ='2025年12月分析データ表'!F8 -> 814710 | P24: ='2025年12月分析データ表'!G8 -> 8 | Q24: ='2025年12月分析データ表'!H8 -> 0.11227802 | R24: ='2026年1月分析データ表'!F8 -> 759373 | S24: ='2026年1月分析データ表'!G8 -> 11 | T24: ='2026年1月分析データ表'!H8 -> 0.11308139 | U24: ='2026年２月分析データ表'!F8 -> 835699 | V24: ='2026年２月分析データ表'!G8 -> 11 | W24: ='2026年２月分析データ表'!H8 -> 0.16342345 | X24: ='2026年3月分析データ表'!F8 -> 799072 | Y24: ='2026年3月分析データ表'!G8 -> 7 | Z24: ='2026年3月分析データ表'!H8 -> 0.1134005 | AA24: 724630 | AB24: 4 | AC24: 0.075
F25: 18 | G25: Trip.com | I25: ='2025年10月分析データ表'!F9 -> 1485910 | J25: ='2025年10月分析データ表'!G9 -> 19 | K25: ='2025年10月分析データ表'!H9 -> 0.22054804 | L25: ='2025年11月分析データ表'!F9 -> 1189320 | M25: ='2025年11月分析データ表'!G9 -> 16 | N25: ='2025年11月分析データ表'!H9 -> 0.16799878 | O25: ='2025年12月分析データ表'!F9 -> 426790 | P25: ='2025年12月分析データ表'!G9 -> 5 | Q25: ='2025年12月分析データ表'!H9 -> 0.058817417 | R25: ='2026年1月分析データ表'!F9 -> 501860 | S25: ='2026年1月分析データ表'!G9 -> 3 | T25: ='2026年1月分析データ表'!H9 -> 0.074734062 | U25: ='2026年２月分析データ表'!F9 -> 0 | V25: ='2026年２月分析データ表'!G9 -> 0 | W25: ='2026年２月分析データ表'!H9 -> 0 | X25: ='2026年3月分析データ表'!F9 -> 20850 | Y25: ='2026年3月分析データ表'!G9 -> 1 | Z25: ='2026年3月分析データ表'!H9 -> 0.002958933 | AA25: 648680 | AB25: 2 | AC25: 0.067
F26: 19 | G26: じゃらん | I26: ='2025年10月分析データ表'!F10 -> 0 | J26: ='2025年10月分析データ表'!G10 -> 0 | K26: ='2025年10月分析データ表'!H10 -> 0 | L26: ='2025年11月分析データ表'!F10 -> 0 | M26: ='2025年11月分析データ表'!G10 -> 0 | N26: ='2025年11月分析データ表'!H10 -> 0 | O26: ='2025年12月分析データ表'!F10 -> 60082 | P26: ='2025年12月分析データ表'!G10 -> 2 | Q26: ='2025年12月分析データ表'!H10 -> 0.0082801098 | R26: ='2026年1月分析データ表'!F10 -> 79300 | S26: ='2026年1月分析データ表'!G10 -> 2 | T26: ='2026年1月分析データ表'!H10 -> 0.011808893 | U26: ='2026年２月分析データ表'!F10 -> 0 | V26: ='2026年２月分析データ表'!G10 -> 0 | W26: ='2026年２月分析データ表'!H10 -> 0 | X26: ='2026年3月分析データ表'!F10 -> 146400 | Y26: ='2026年3月分析データ表'!G10 -> 1 | Z26: ='2026年3月分析データ表'!H10 -> 0.020776393 | AA26: 55600 | AB26: 1 | AC26: 0.006
F27: 20 | G27: 一休.com | I27: ='2025年10月分析データ表'!F11 -> 0 | J27: ='2025年10月分析データ表'!G11 -> 0 | K27: ='2025年10月分析データ表'!H11 -> 0 | L27: ='2025年11月分析データ表'!F11 -> 114264 | M27: ='2025年11月分析データ表'!G11 -> 6 | N27: ='2025年11月分析データ表'!H11 -> 0.016140495 | O27: ='2025年12月分析データ表'!F11 -> 107450 | P27: ='2025年12月分析データ表'!G11 -> 7 | Q27: ='2025年12月分析データ表'!H11 -> 0.014808059 | R27: ='2026年1月分析データ表'!F11 -> 333073 | S27: ='2026年1月分析データ表'!G11 -> 9 | T27: ='2026年1月分析データ表'!H11 -> 0.049599287 | U27: ='2026年２月分析データ表'!F11 -> 113933 | V27: ='2026年２月分析データ表'!G11 -> 4 | W27: ='2026年２月分析データ表'!H11 -> 0.022279941 | X27: ='2026年3月分析データ表'!F11 -> 192160 | Y27: ='2026年3月分析データ表'!G11 -> 1 | Z27: ='2026年3月分析データ表'!H11 -> 0.027270435 | AA27: 0 | AB27: 0 | AC27: 0
F28: 21 | G28: 自社 | I28: ='2025年10月分析データ表'!F12 -> 0 | J28: ='2025年10月分析データ表'!G12 -> 0 | K28: ='2025年10月分析データ表'!H12 -> 0 | L28: ='2025年11月分析データ表'!F12 -> 0 | M28: ='2025年11月分析データ表'!G12 -> 0 | N28: ='2025年11月分析データ表'!H12 -> 0 | O28: ='2025年12月分析データ表'!F12 -> 829000 | P28: ='2025年12月分析データ表'!G12 -> 11 | Q28: ='2025年12月分析データ表'!H12 -> 0.11424738 | R28: ='2026年1月分析データ表'!F12 -> 465000 | S28: ='2026年1月分析データ表'!G12 -> 5 | T28: ='2026年1月分析データ表'!H12 -> 0.069245086 | U28: ='2026年２月分析データ表'!F12 -> 241488 | V28: ='2026年２月分析データ表'!G12 -> 4 | W28: ='2026年２月分析データ表'!H12 -> 0.047223705 | X28: ='2026年3月分析データ表'!F12 -> 0 | Y28: ='2026年3月分析データ表'!G12 -> 0 | Z28: ='2026年3月分析データ表'!H12 -> 0 | AA28: 80000 | AB28: 2 | AC28: 0.008
F29: 22 | G29: 合計 | I29: ='2025年10月分析データ表'!F13 -> 6737353 | J29: ='2025年10月分析データ表'!G13 -> 73 | K29: ='2025年10月分析データ表'!H13 -> 1 | L29: ='2025年11月分析データ表'!F13 -> 7079337 | M29: ='2025年11月分析データ表'!G13 -> 83 | N29: ='2025年11月分析データ表'!H13 -> 1 | O29: ='2025年12月分析データ表'!F13 -> 7256184 | P29: ='2025年12月分析データ表'!G13 -> 84 | Q29: ='2025年12月分析データ表'!H13 -> 1 | R29: ='2026年1月分析データ表'!F13 -> 6715278 | S29: ='2026年1月分析データ表'!G13 -> 68 | T29: ='2026年1月分析データ表'!H13 -> 1 | U29: ='2026年２月分析データ表'!F13 -> 5113703 | V29: ='2026年２月分析データ表'!G13 -> 55 | W29: ='2026年２月分析データ表'!H13 -> 1 | X29: ='2026年3月分析データ表'!F13 -> 7046459 | Y29: ='2026年3月分析データ表'!G13 -> 64 | Z29: ='2026年3月分析データ表'!H13 -> 1 | AA29: =SUM(AA21:AA28) -> 9682526 | AB29: =SUM(AB21:AB28) -> 62 | AC29: =SUM(AC21:AC28) -> 1

Sheet 2026年4月予約一覧表
A1: =SUM(A3:A67) -> 62 | F1: =SUM(F3:F67) -> 239 | I1: =SUM(I3:I64) -> 65 | L1: =SUM(L3:L67) -> 143 | M1: =SUM(M3:M67) -> 22 | N1: =SUM(N3:N67) -> 9682526 | O1: =SUM(O3:O67) -> 1259171 | P1: =SUM(P3:P67) -> 7986574 | Q1: =SUM(Q3:Q67) -> 1281972 | R1: =SUM(R3:R64) -> 162210 | S1: =SUM(S3:S64) -> 8238344 | T1: =SUM(T3:T64) -> 8238344 | V1: =SUM(V3:V64) -> 0 | X1: =SUM(X3:X64) -> 648
B2: 予約番号 | C2: チェックイン日 | D2: チェックアウト日 | E2: 予約日 | F2: 泊数 | G2: 予約サイト | H2: 部屋タイプ名称 | I2: 室数 | J2: ゲスト名 | K2: 国・地域 | L2: 大人 | M2: 子供 | N2: 予約合計額 | O2: OTA サービス料 | P2: 受取金 | Q2: サービス料 | R2: クレジットカード手数料 | S2: サイド別銀行 入金小計 | T2: 銀行入金小計 | U2: 入金日 | V2: ポイント割引額 | W2: 決済方法 | X2: 泊延べ日数
A3: 1 | B3: 5513278707 | C3: 46103 | D3: 46115 | E3: 46024 | F3: 12 | G3: Booking | H3: LAKU 29.9㎡ | I3: 1 | J3: Nur Amirah Mohd Isa | K3: Australia | L3: 2 | M3: 0 | N3: 406320 | O3: 58103 | P3: 348217 | Q3: 48758 | R3: 9345 | S3: =N3-Q3-R3 -> 348217 | T3: =S3 -> 348217 | U3: 46150 | W3: 事前決済 | X3: =F3*(L3+M3) -> 24
A4: 1 | B4: 6476172510 | C4: 46110 | D4: 46113 | E4: 46098 | F4: 3 | G4: Booking | H4: LAKU 29.9㎡ | I4: 1 | J4: Rob Meijers | K4: America | L4: 2 | M4: 0 | N4: 81060 | O4: 0 | P4: 75060 | Q4: 12159 | R4: 1864 | S4: =N4-Q4-R4 -> 67037 | T4: =S4 -> 67037 | U4: 46115 | W4: 事前決済 | X4: =F4*(L4+M4) -> 6
A5: 1 | B5: 6499912090 | C5: 46111 | D5: 46115 | E5: 46031 | F5: 4 | G5: Booking | H5: LAKU 29.9㎡ | I5: 1 | J5: Rebecca Stinson | K5: Australia | L5: 2 | M5: 0 | N5: 156120 | O5: 22325 | P5: 133795 | Q5: 18734 | R5: 3591 | S5: =N5-Q5-R5 -> 133795 | T5: =S5 -> 133795 | U5: 46150 | W5: 事前決済 | X5: =F5*(L5+M5) -> 8
A6: 1 | B6: 5742481816 | C6: 46111 | D6: 46114 | E6: 46025 | F6: 3 | G6: Booking | H6: LAKU 36.7㎡ | I6: 2 | J6: Raymond Foo | K6: Canada | L6: 2 | M6: 1 | N6: =129525+166582 -> 296107 | O6: 22353 | P6: 107172 | Q6: 35533 | R6: 6810 | S6: =N6-Q6-R6 -> 253764 | T6: =S6 -> 253764 | U6: 46150 | W6: 事前決済 | X6: =F6*(L6+M6) -> 9
A7: 1 | B7: 6452763897 | C7: 46112 | D7: 46115 | E7: 46109 | F7: 3 | G7: Booking | H7: LAKU 43.1㎡ | I7: 1 | J7: Brent Jurmu | K7: Japan | L7: 3 | M7: 0 | N7: 70438 | O7: 12186 | P7: 58252 | Q7: 10566 | R7: 1620 | S7: =N7-Q7-R7 -> 58252 | T7: =S7 -> 58252 | U7: 46150 | W7: 事前決済 | X7: =F7*(L7+M7) -> 9
A8: 1 | B8: 5991560801 | C8: 46114 | D8: 46115 | E8: 46101 | F8: 1 | G8: Booking | H8: LAKU 36.7㎡ | I8: 1 | J8: Yoshida Keiji | K8: Japan | L8: 2 | M8: 2 | N8: 40160 | O8: 6948 | P8: 33212 | Q8: 6024 | R8: 924 | S8: =N8-Q8-R8 -> 33212 | T8: =S8 -> 33212 | U8: 46150 | W8: 事前決済 | X8: =F8*(L8+M8) -> 4
A9: 1 | B9: 6207646306 | C9: 46114 | D9: 46116 | E9: 46098 | F9: 2 | G9: Booking | H9: LAKU 29.9㎡ | I9: 1 | J9: Karen Chen | K9: America | L9: 3 | M9: 0 | N9: 103578 | O9: 17919 | P9: 85659 | Q9: 15537 | R9: 2382 | S9: =N9-Q9-R9 -> 85659 | T9: =S9 -> 85659 | U9: 46150 | W9: 事前決済 | X9: =F9*(L9+M9) -> 6
A10: 1 | B10: 6682072900 | C10: 46114 | D10: 46115 | E10: 46098 | F10: 1 | G10: Booking | H10: LAKU 36.7㎡ | I10: 1 | J10: Mana Kawai | K10: Japan | L10: 2 | M10: 0 | N10: 25215 | O10: 4362 | P10: 20853 | Q10: 3782 | R10: 580 | S10: =N10-Q10-R10 -> 20853 | T10: =S10 -> 20853 | U10: 46150 | W10: 事前決済 | X10: =F10*(L10+M10) -> 2
A11: 1 | B11: 6375677983 | C11: 46115 | D11: 46116 | E11: 46088 | F11: 1 | G11: Booking | H11: LAKU 43.1㎡ | I11: 1 | J11: KUKI KAORU | K11: Japan | L11: 3 | M11: 2 | N11: 54333 | O11: 7770 | P11: 46563 | Q11: 6520 | R11: 1250 | S11: =N11-Q11-R11 -> 46563 | T11: =S11 -> 46563 | U11: 46150 | W11: 事前決済 | X11: =F11*(L11+M11) -> 5
A12: 1 | B12: 5440457575 | C12: 46115 | D12: 46117 | E12: 46109 | F12: 2 | G12: Booking | H12: LAKU 60.22㎡ | I12: 1 | J12: Astrid Reitz | K12: Switzerland | L12: 2 | M12: 2 | N12: 141000 | O12: 24393 | P12: 116607 | Q12: 21150 | R12: 3243 | S12: =N12-Q12-R12 -> 116607 | T12: =S12 -> 116607 | U12: 46150 | W12: 事前決済 | X12: =F12*(L12+M12) -> 8
A13: 1 | B13: 6329474212 | C13: 46115 | D13: 46121 | E13: 46040 | F13: 6 | G13: Booking | H13: LAKU 29.9㎡ | I13: 1 | J13: Vanessa Suemi Uesugi | K13: Brazil | L13: 2 | M13: 0 | N13: 231180 | O13: 33059 | P13: 198121 | Q13: 27742 | R13: 5317 | S13: =N13-Q13-R13 -> 198121 | T13: =S13 -> 198121 | U13: 46150 | W13: 事前決済 | X13: =F13*(L13+M13) -> 12
A14: 1 | B14: 6039939329 | C14: 46115 | D14: 46119 | E14: 46055 | F14: 4 | G14: Booking | H14: LAKU 29.9㎡ | I14: 1 | J14: YiTing Hsu | K14: Taiwan | L14: 3 | M14: 0 | N14: 201156 | O14: 28766 | P14: 172390 | Q14: 24139 | R14: 4627 | S14: =N14-Q14-R14 -> 172390 | T14: =S14 -> 172390 | U14: 46150 | W14: 事前決済 | X14: =F14*(L14+M14) -> 12
A15: 1 | B15: 6401963673 | C15: 46115 | D15: 46116 | E15: 46058 | F15: 1 | G15: Booking | H15: LAKU 36.7㎡ | I15: 2 | J15: Kusuma Chongvisal | K15: Thailand | L15: 2 | M15: 0 | N15: =47175+47175 -> 94350 | O15: 7831 | P15: 39344 | Q15: 11322 | R15: 2170 | S15: =N15-Q15-R15 -> 80858 | T15: =S15 -> 80858 | U15: 46150 | W15: 事前決済 | X15: =F15*(L15+M15) -> 2
A16: 1 | B16: 5552259360 | C16: 46116 | D16: 46118 | E16: 46034 | F16: 2 | G16: Booking | H16: LAKU 36.7㎡ | I16: 2 | J16: kusuma mutitaskul | K16: Thailand | L16: 2 | M16: 0 | N16: =88350+88350 -> 176700 | O16: 14666 | P16: 73684 | Q16: 21204 | R16: 4064 | S16: =N16-Q16-R16 -> 151432 | T16: =S16 -> 151432 | U16: 46150 | W16: 事前決済 | X16: =F16*(L16+M16) -> 4
A17: 1 | B17: 5577699383 | C17: 46116 | D17: 46120 | E17: 46046 | F17: 4 | G17: Booking | H17: LAKU 29.9㎡ | I17: 1 | J17: Jeremy Gibbons | K17: United Kingdom | L17: 2 | M17: 0 | N17: 156120 | O17: 22325 | P17: 133795 | Q17: 18734 | R17: 3591 | S17: =N17-Q17-R17 -> 133795 | T17: =S17 -> 133795 | U17: 46150 | W17: 事前決済 | X17: =F17*(L17+M17) -> 8
A18: 1 | B18: 5531975761 | C18: 46117 | D18: 46123 | E18: 46101 | F18: 6 | G18: Booking | H18: LAKU 60.22㎡ | I18: 1 | J18: Kiki Abels | K18: Netherlands | L18: 4 | M18: 0 | N18: 276000 | O18: 47748 | P18: 228252 | Q18: 41400 | R18: 6348 | S18: =N18-Q18-R18 -> 228252 | T18: =S18 -> 228252 | U18: 46150 | W18: 事前決済 | X18: =F18*(L18+M18) -> 24
A19: 1 | B19: 6508781956 | C19: 46118 | D19: 46121 | E19: 46095 | F19: 3 | G19: Booking | H19: LAKU 36.7㎡ | I19: 1 | J19: Sabrina Gross | K19: United Kingdom | L19: 1 | M19: 0 | N19: 80115 | O19: 13860 | P19: 66255 | Q19: 12017 | R19: 1843 | S19: =N19-Q19-R19 -> 66255 | T19: =S19 -> 66255 | U19: 46150 | W19: 事前決済 | X19: =F19*(L19+M19) -> 3
A20: 1 | B20: 6774421891 | C20: 46118 | D20: 46120 | E20: 46086 | F20: 2 | G20: Booking | H20: LAKU 43.1㎡ | I20: 1 | J20: jean-gabriel pointeau | K20: France | L20: 2 | M20: 2 | N20: 131665 | O20: 18828 | P20: 112837 | Q20: 15800 | R20: 3028 | S20: =N20-Q20-R20 -> 112837 | T20: =S20 -> 112837 | U20: 46150 | W20: 事前決済 | X20: =F20*(L20+M20) -> 8
A21: 1 | B21: 6246263907 | C21: 46119 | D21: 46121 | E21: 46047 | F21: 2 | G21: Booking | H21: LAKU 46.64㎡ | I21: 1 | J21: Cassandra Benjamin | K21: America | L21: 3 | M21: 0 | N21: 110755 | O21: 15838 | P21: 94917 | Q21: 13291 | R21: 2547 | S21: =N21-Q21-R21 -> 94917 | T21: =S21 -> 94917 | U21: 46150 | W21: 事前決済 | X21: =F21*(L21+M21) -> 6
A22: 1 | B22: 6551582584 | C22: 46119 | D22: 46122 | E22: 46118 | F22: 3 | G22: Booking | H22: LAKU 29.9㎡ | I22: 1 | J22: Louis Morris | K22: United Kingdom | L22: 2 | M22: 0 | N22: 51036 | O22: 8829 | P22: 42207 | Q22: 7655 | R22: 1174 | S22: =N22-Q22-R22 -> 42207 | T22: =S22 -> 42207 | U22: 46150 | W22: 事前決済 | X22: =F22*(L22+M22) -> 6
A23: 1 | B23: 5305848845 | C23: 46120 | D23: 46128 | E23: 46029 | F23: 8 | G23: Booking | H23: LAKU 43.1㎡ | I23: 1 | J23: Le Wang | K23: Australia | L23: 2 | M23: 2 | N23: 392662 | O23: 56150 | P23: 336512 | Q23: 47119 | R23: 9031 | S23: =N23-Q23-R23 -> 336512 | T23: =S23 -> 336512 | U23: 46150 | W23: 事前決済 | X23: =F23*(L23+M23) -> 32
A24: 1 | B24: 5070127519 | C24: 46120 | D24: 46126 | E24: 46079 | F24: 6 | G24: Booking | H24: LAKU 29.9㎡ | I24: 1 | J24: Julien Murigneux | K24: France | L24: 2 | M24: 0 | N24: 226176 | O24: 32343 | P24: 193833 | Q24: 27141 | R24: 5202 | S24: =N24-Q24-R24 -> 193833 | T24: =S24 -> 193833 | U24: 46150 | W24: 事前決済 | X24: =F24*(L24+M24) -> 12
A25: 1 | B25: 5221408297 | C25: 46121 | D25: 46123 | E25: 46116 | F25: 2 | G25: Booking | H25: LAKU 29.9㎡ | I25: 1 | J25: Nancy Demuynck | K25: Australia | L25: 3 | M25: 0 | N25: 58692 | O25: 10154 | P25: 48538 | Q25: 8804 | R25: 1350 | S25: =N25-Q25-R25 -> 48538 | T25: =S25 -> 48538 | U25: 46150 | W25: 事前決済 | X25: =F25*(L25+M25) -> 6
A26: 1 | B26: 5743915140 | C26: 46121 | D26: 46124 | E26: 46118 | F26: 3 | G26: Booking | H26: LAKU 36.7㎡ | I26: 1 | J26: Nargiza Tashybekova | K26: Korea | L26: 2 | M26: 0 | N26: 52116 | O26: 9016 | P26: 43100 | Q26: 7817 | R26: 1199 | S26: =N26-Q26-R26 -> 43100 | T26: =S26 -> 43100 | U26: 46150 | W26: 事前決済 | X26: =F26*(L26+M26) -> 6
A27: 1 | B27: 6697823605 | C27: 46121 | D27: 46125 | E27: 46036 | F27: 4 | G27: Booking | H27: LAKU 36.7㎡ | I27: 1 | J27: Dylan Armut | K27: Belgium | L27: 2 | M27: 1 | N27: 170700 | O27: 24410 | P27: 146290 | Q27: 20484 | R27: 3926 | S27: =N27-Q27-R27 -> 146290 | T27: =S27 -> 146290 | U27: 46150 | W27: 事前決済 | X27: =F27*(L27+M27) -> 12
A28: 1 | B28: 6875160161 | C28: 46122 | D28: 46125 | E28: 46062 | F28: 3 | G28: Booking | H28: LAKU 29.9㎡ | I28: 1 | J28: WU CHONG WEI | K28: Taiwan | L28: 2 | M28: 0 | N28: 118590 | O28: 16959 | P28: 101631 | Q28: 14231 | R28: 2728 | S28: =N28-Q28-R28 -> 101631 | T28: =S28 -> 101631 | U28: 46150 | W28: 事前決済 | X28: =F28*(L28+M28) -> 6
... A49: 1 | B49: 6206369924 | C49: 46136 | D49: 46138 | E49: 46127 | F49: 2 | G49: Booking | H49: LAKU 60.22㎡ | I49: 1 | J49: Silvio Bruinsma | K49: New Zealand | L49: 2 | M49: 2 | N49: 49200 | O49: 8512 | P49: 40688 | Q49: 7380 | R49: 1132 | S49: =N49-Q49-R49 -> 40688 | T49: =S49 -> 40688 | U49: 46150 | W49: 事前決済 | X49: =F49*(L49+M49) -> 8
A50: 1 | B50: HM5TYFRMAD | C50: 46111 | D50: 46117 | E50: 45989 | F50: 6 | G50: Airbnb | H50: LAKU 43.1㎡ | I50: 1 | J50: Hernan Gustavo Garciamelan | K50: America | L50: 2 | M50: 2 | N50: 364200 | O50: 56451 | P50: 307749 | Q50: 56451 | R50: 0 | S50: =N50-Q50-R50 -> 307749 | T50: =S50 -> 307749 | U50: 46113 | W50: 事前決済 | X50: =F50*(L50+M50) -> 24
A51: 1 | B51: HMKHE2ZAXF | C51: 46132 | D51: 46136 | E51: 46129 | F51: 4 | G51: Airbnb | H51: LAKU 36.7㎡ | I51: 1 | J51: Abdul Mattin | K51: Indonesia | L51: 2 | M51: 0 | N51: 62120 | O51: 9629 | P51: 52491 | Q51: 9629 | R51: 0 | S51: =N51-Q51-R51 -> 52491 | T51: =S51 -> 52491 | U51: 46134 | W51: 事前決済 | X51: =F51*(L51+M51) -> 8
A52: 1 | B52: HMPCNN28FB | C52: 46137 | D52: 46139 | E52: 46133 | F52: 2 | G52: Airbnb | H52: LAKU 29.9㎡ | I52: 1 | J52: 김 혜환 | K52: Korea | L52: 2 | M52: 0 | N52: 30808 | O52: 4775 | P52: 26033 | Q52: 4775 | R52: 0 | S52: =N52-Q52-R52 -> 26033 | T52: =S52 -> 26033 | U52: 46139 | W52: 事前決済 | X52: =F52*(L52+M52) -> 4
A53: 1 | B53: 602874159 | C53: 46116 | D53: 46124 | E53: 45990 | F53: 8 | G53: Agoda | H53: LAKU 43.1㎡ | I53: 1 | J53: Kin Man Yeung | K53: Hong Kong | L53: 2 | M53: 1 | N53: 435624 | O53: 0 | P53: 383352 | Q53: 52272 | R53: 0 | S53: =N53-Q53-R53 -> 383352 | T53: =S53 -> 383352 | W53: 事前決済 | X53: =F53*(L53+M53) -> 24
A54: 1 | B54: 1704023459 | C54: 46116 | D54: 46118 | E54: 46083 | F54: 2 | G54: Agoda | H54: LAKU 46.64㎡ | I54: 1 | J54: Weijai Chang | K54: Taiwan | L54: 3 | M54: 0 | N54: 139856 | O54: 16782 | P54: 123074 | Q54: 16782 | R54: 0 | S54: =N54-Q54-R54 -> 123074 | T54: =S54 -> 123074 | W54: 事前決済 | X54: =F54*(L54+M54) -> 6
A55: 1 | B55: 1990849871 | C55: 46125 | D55: 46128 | E55: 46093 | F55: 3 | G55: Agoda | H55: LAKU 36.7㎡ | I55: 1 | J55: Mikhail Khvochtchev | K55: Thailand | L55: 2 | M55: 0 | N55: 88350 | O55: 10602 | P55: 77748 | Q55: 10602 | R55: 0 | S55: =N55-Q55-R55 -> 77748 | T55: =S55 -> 77748 | W55: 事前決済 | X55: =F55*(L55+M55) -> 6
A56: 1 | B56: 2392389259 | C56: 46111 | D56: 46115 | E56: 46066 | F56: 4 | G56: Expedia | H56: LAKU 60.22㎡ | I56: 1 | J56: Michael Hoenmans | K56: America | L56: 3 | M56: 0 | N56: 276588 | O56: 48596 | P56: 227992 | Q56: 48596 | R56: 0 | S56: =N56-Q56-R56 -> 227992 | T56: =S56 -> 227992 | W56: 事前決済 | X56: =F56*(L56+M56) -> 12
A57: 1 | B57: 2366141968 | C57: 46125 | D57: 46130 | E57: 46030 | F57: 5 | G57: Expedia | H57: LAKU 43.1㎡ | I57: 1 | J57: Ray Siu | K57: America | L57: 3 | M57: 0 | N57: 248265 | O57: 43500 | P57: 204765 | Q57: 43500 | R57: 0 | S57: =N57-Q57-R57 -> 204765 | T57: =S57 -> 204765 | W57: 事前決済 | X57: =F57*(L57+M57) -> 15
A58: 1 | B58: 2433931511 | C58: 46126 | D58: 46129 | E58: 46121 | F58: 3 | G58: Expedia | H58: LAKU 29.9㎡ | I58: 1 | J58: kristy duong | K58: America | L58: 1 | M58: 0 | N58: 69652 | O58: 11350 | P58: 58302 | Q58: 11350 | R58: 0 | S58: =N58-Q58-R58 -> 58302 | T58: =S58 -> 58302 | W58: 事前決済 | X58: =F58*(L58+M58) -> 3
A59: 1 | B59: 2386183057 | C59: 46129 | D59: 46132 | E59: 46058 | F59: 3 | G59: Expedia | H59: LAKU 36.7㎡ | I59: 1 | J59: YUCHEN HUANG | K59: China | L59: 2 | M59: 0 | N59: 130125 | O59: 22236 | P59: 107889 | Q59: 22236 | R59: 0 | S59: =N59-Q59-R59 -> 107889 | T59: =S59 -> 107889 | W59: 事前決済 | X59: =F59*(L59+M59) -> 6
A60: 1 | B60: 20251109180515 | C60: 46107 | D60: 46116 | E60: 45970 | F60: 9 | G60: Trip.com | H60: LAKU 46.64㎡ | I60: 1 | J60: SUNG YEN HSIEH | K60: Taiwan | L60: 3 | M60: 0 | N60: 529800 | O60: 0 | P60: 466944 | Q60: 62856 | R60: 0 | S60: 466944 | T60: =S60 -> 466944 | U60: 46160 | W60: 事前決済 | X60: =F60*(L60+M60) -> 27
...

Sheet 2026年月4分析データ表
B2: ホテル運営分析データ表(2026年4月分） | J2: 部屋番号 | K2: 客室タイプごとの平均宿泊人数（1泊あたり） | L2: 客室数 | M2: 面積（㎡） | O2: 総売上（円） | P2: 客室タイプごとの稼働率 | Q2: 実販売室泊（室泊） | R2: 宿泊延べ日数（人泊）※ | S2: 販売可能室泊（室泊） | T2: ADR（平均客室単価） | U2: 人数単価（人均単価：1人あたり） | V2: RevPAR（1室当たり収益） | W2: ㎡単価（日額）＝「1㎡あたり1日」
B3: ① 物件基本情報 | E3: ③ 客源平台（チャネル別） | J3: 101 | K3: =R3/Q3 -> 2.1111111 | L3: 3 | M3: 29.9 | N3: =L3*M3 -> 89.7 | O3: 2873204 | P3: =Q3/(L3*C22)*100% -> 1 | Q3: 90 | R3: 190 | S3: =L3*C22 -> 90 | T3: =O3/Q3 -> 31924.489 | U3: =O3/R3 -> 15122.126 | V3: =O3/S3 -> 31924.489 | W3: =IFERROR(O3/(N3*C22),0) -> 1067.7087
B4: A（項目） | C4: B（値） | E4: D（チャネル） | F4: E（売上） | G4: F（予約件数） | H4: G（売上構成比） | J4: 201
B5: 分析開始日（チェクアウト日基準） | C5: 46113 | E5: Booking.com | F5: 7052658 | G5: 47 | H5: =IFERROR(F5/$F$12,0) -> 0.7283903 | J5: 301
B6: 分析終了日（チェクアウト日基準） | C6: 46142 | E6: Expedia | F6: 724630 | G6: 4 | H6: =IFERROR(F6/$F$12,0) -> 0.074838942 | J6: 102 | K6: =R6/Q6 -> 2.2 | L6: 2 | M6: 36.7 | N6: =L6*M6 -> 73.4 | O6: 1672015 | P6: =Q6/S6*100% -> 0.75 | Q6: =45 -> 45 | R6: 99 | S6: =L6*C22 -> 60 | T6: =O6/Q6 -> 37155.889 | U6: =O6/R6 -> 16889.04 | V6: =O6/S6 -> 27866.917 | W6: =IFERROR(O6/(N6*C22),0) -> 759.31653
B7: 延床面積（㎡） | C7: 356 | E7: Agoda | F7: 663830 | G7: 3 | H7: =IFERROR(F7/$F$12,0) -> 0.068559589 | J7: 402
B8: 客室数 | C8: 9 | E8: Trip | F8: 648680 | G8: 2 | H8: =IFERROR(F8/$F$12,0) -> 0.066994914 | J8: 202 | K8: =R8/Q8 -> 3.2692308 | L8: 2 | M8: 43.1 | N8: =L8*M8 -> 86.2 | O8: 2430729 | P8: =Q8/S8*100% -> 0.86666667 | Q8: 52 | R8: 170 | S8: =L8*C22 -> 60 | T8: =O8/Q8 -> 46744.788 | U8: =O8/R8 -> 14298.406 | V8: =O8/S8 -> 40512.15 | W8: =IFERROR(O8/(N8*C22),0) -> 939.95708
B9: 総売上（円） | C9: ='2026年4月予約一覧表'!N1 -> 9682526 | E9: Airbnb | F9: 457128 | G9: 3 | H9: =IFERROR(F9/$F$12,0) -> 0.047211647 | J9: 302
B10: 総宿泊人数（人） | C10: ='2026年4月予約一覧表'!L1+'2026年4月予約一覧表'!M1 -> 165 | E10: 自社予約 | F10: 80000 | G10: 2 | H10: =IFERROR(F10/$F$12,0) -> 0.0082623068 | J10: 403 | K10: =R10/Q10 -> 3.2333333 | L10: 1 | M10: 46.64 | O10: 1557290 | P10: =Q10/S10*100% -> 1 | Q10: 30 | R10: 97 | S10: =L10*C22 -> 30 | T10: =O10/Q10 -> 51909.667 | U10: =O10/R10 -> 16054.536 | V10: =O10/S10 -> 51909.667 | W10: =IFERROR(O10/(M10*C22),0) -> 1112.986
B11: 宿泊延べ日数（人泊）※ | C11: ='2026年4月予約一覧表'!X1 -> 648 | E11: じゃらん | F11: 55600 | G11: 1 | H11: =IFERROR(F11/$F$12,0) -> 0.0057423032 | J11: 401 | K11: =R11/Q11 -> 4.1818182 | L11: 1 | M11: 60.22 | O11: 1149288 | P11: =Q11/S11*100% -> 0.73333333 | Q11: 22 | R11: 92 | S11: =L11*C22 -> 30 | T11: =O11/Q11 -> 52240.364 | U11: =O11/R11 -> 12492.261 | V11: =O11/S11 -> 38309.6 | W11: =IFERROR(O11/(M11*C22),0) -> 636.16074
B12: 販売可能室数（室） | C12: 9 | E12: 合計 | F12: =SUM(F5:F11) -> 9682526 | G12: =SUM(G5:G11) -> 62 | H12: =IFERROR(F12/$F$12,0) -> 1 | L12: =SUM(L3:L11) -> 9 | M12: =(M3*L3)+(L6*M6)+(L8*M8)+M10+M11 -> 356.16 | O12: =SUM(O3:O11) -> 9682526 | Q12: =SUM(Q3:Q11) -> 239 | R12: =SUM(R3:R11) -> 648 | S12: =SUM(S3:S11) -> 270
B13: 販売可能室泊（室泊） | C13: =C8*C22 -> 270
B14: 実販売室泊（室泊） | C14: ='2026年4月予約一覧表'!F1 -> 239
B15: キャンセル件数（件） | C15: 38
B16: 予約総件数（件） | C16: ='2026年4月予約一覧表'!A1 -> 62
B17: キャンセル室泊（室泊） | C17: 160
B18: ※「宿泊延べ日数（人泊）」＝各予約の「人数×泊数」の合計（人泊）。
B19: 「実販売室泊（室泊）」＝各予約の「室数×泊数」の合計（室泊）。
B21: ② 計算（自動）
B22: 期間日数（日数） | C22: =DATEDIF(C5,C6,"D")+1 -> 30
B23: 稼働率（OCC） | C23: =IFERROR(C14/C13,0) -> 0.88518519
B24: ADR（平均客室単価） | C24: =IFERROR(C9/C14,0) -> 40512.661
B25: 人数単価（人均単価：1人あたり） | C25: =IFERROR(C9/C11,0) -> 14942.17
B26: RevPAR（1室当たり収益） | C26: =IFERROR(C9/C13,0) -> 35861.207
B27: ㎡単価（日額）＝「1㎡あたり1日」 | C27: =IFERROR(C9/(C7*C22),0) -> 906.60356
B28: 取消率（件数ベース） | C28: =IFERROR(C15/C16,0) -> 0.61290323
B29: 取消稼働率（室泊ベース） | C29: =IFERROR(C17/(C14+C17),0) -> 0.40100251

Sheet 2025年10月予約一覧表
D2: =SUM(D4:D76) -> 239 | E2: =SUM(E4:E76) -> 609 | H2: =SUM(H4:H76) -> 73 | J2: =SUM(J4:J76) -> 186 | K2: =SUM(K4:K77) -> 6737353 | L2: =SUM(L4:L77) -> 880342 | M2: =SUM(M4:M77) -> 29067 | N2: =SUM(N4:N77) -> 5827944 | O2: =SUM(O4:O77) -> 5827944 | P2: =SUM(P4:P77) -> 0
B3: チェックイン日 | C3: チェックアウト日 | D3: 泊数 | E3: 宿泊延べ日数 | F3: 予約サイト名称 | G3: 部屋タイプ名称 | H3: 室数 | I3: 宿泊者氏名 | J3: 大人人数計 | K3: 予約合計額 | L3: サービス料 | M3: クレジットカード手数料 | N3: サイト別銀行入金小計 | O3: 銀行入金小計 | P3: ポイント額 | Q3: 決済方法
B4: 2025/10/01 | C4: 2025/10/03 | D4: 2 | E4: =D4*J4 -> 6 | F4: Agoda | G4: 46.64平米403室 | H4: 1 | I4: lin wen syuan | J4: 3 | K4: 52560 | L4: 6308 | M4: 0 | O4: =K4-L4-M4 -> 46252 | P4: 0 | Q4: 事前決済
B5: 2025/10/07 | C5: 2025/10/09 | D5: 2 | E5: =D5*J5 -> 4 | F5: Agoda | G5: 29.90平米101室201室301室 | H5: 1 | I5: Tinnie Tsz Yan Lam | J5: 2 | K5: 61160 | L5: 7340 | M5: 0 | O5: =K5-L5-M5 -> 53820 | P5: 0 | Q5: 事前決済
B6: 2025/10/05 | C6: 2025/10/10 | D6: 5 | E6: =D6*J6 -> 10 | F6: Agoda | G6: 36.70平米102室402室 | H6: 1 | I6: Aziz Dolce | J6: 2 | K6: 137150 | L6: 16458 | M6: 0 | O6: =K6-L6-M6 -> 120692 | P6: 0 | Q6: 事前決済
B7: 2025/10/07 | C7: 2025/10/10 | D7: 3 | E7: =D7*J7 -> 12 | F7: Agoda | G7: 60.22平米401室 | H7: 1 | I7: Jihyun Hong | J7: 4 | K7: 108000 | L7: 12960 | M7: 0 | O7: =K7-L7-M7 -> 95040 | P7: 0 | Q7: 事前決済
B8: 2025/10/10 | C8: 2025/10/12 | D8: 2 | E8: =D8*J8 -> 8 | F8: Agoda | G8: 60.22平米401室 | H8: 1 | I8: JONGHWAN CHUNG | J8: 4 | K8: 76000 | L8: 9120 | M8: 0 | O8: =K8-L8-M8 -> 66880 | P8: 0 | Q8: 事前決済
B9: 2025/10/11 | C9: 2025/10/13 | D9: 2 | E9: =D9*J9 -> 10 | F9: Agoda | G9: 46.64平米403室 | H9: 1 | I9: Michael Moppett | J9: 5 | K9: 81712 | L9: 9806 | M9: 0 | O9: =K9-L9-M9 -> 71906 | P9: 0 | Q9: 事前決済
B10: 2025/10/11 | C10: 2025/10/14 | D10: 3 | E10: =D10*J10 -> 6 | F10: Agoda | G10: 29.90平米101室201室301室 | H10: 1 | I10: Lo?s Tacher | J10: 2 | K10: 60048 | L10: 7206 | M10: 0 | O10: =K10-L10-M10 -> 52842 | P10: 0 | Q10: 事前決済
B11: 2025/10/13 | C11: 2025/10/17 | D11: 4 | E11: =D11*J11 -> 8 | F11: Agoda | G11: 29.90平米101室201室301室 | H11: 1 | I11: Medvidovic Sanda | J11: 2 | K11: 86620 | L11: 10394 | M11: 0 | O11: =K11-L11-M11 -> 76226 | P11: 0 | Q11: 事前決済
B12: 2025/10/16 | C12: 2025/10/19 | D12: 3 | E12: =D12*J12 -> 6 | F12: Agoda | G12: 36.70平米102室402室 | H12: 1 | I12: LlN CHlUMEl | J12: 2 | K12: 73200 | L12: 8784 | M12: 0 | O12: =K12-L12-M12 -> 64416 | P12: 0 | Q12: 事前決済
B13: 2025/10/16 | C13: 2025/10/21 | D13: 5 | E13: =D13*J13 -> 10 | F13: Agoda | G13: 43.10平米202室302室 | H13: 1 | I13: Grace Wong | J13: 2 | K13: 148220 | L13: 17787 | M13: 0 | O13: =K13-L13-M13 -> 130433 | P13: 0 | Q13: 事前決済
B14: 2025/10/19 | C14: 2025/10/22 | D14: 3 | E14: =D14*J14 -> 6 | F14: Agoda | G14: 29.90平米101室201室301室 | H14: 1 | I14: Natalia Araujo | J14: 2 | K14: 39360 | L14: 4722 | M14: 0 | O14: =K14-L14-M14 -> 34638 | P14: 0 | Q14: 事前決済
B15: 2025/10/19 | C15: 2025/10/23 | D15: 4 | E15: =D15*J15 -> 12 | F15: Agoda | G15: 36.70平米102室402室 | H15: 1 | I15: Nadwa Razan binti Rosli | J15: 3 | K15: 117012 | L15: 14040 | M15: 0 | O15: =K15-L15-M15 -> 102972 | P15: 0 | Q15: 事前決済
... B24: 2025/10/28 | C24: 2025/10/30 | D24: 2 | E24: =D24*J24 -> 2 | F24: Agoda | G24: 36.70平米102室402室 | H24: 1 | I24: Ruth Cooling | J24: 1 | K24: 30400 | L24: 3648 | M24: 0 | O24: =K24-L24-M24 -> 26752 | P24: 0 | Q24: 事前決済
B25: 2025/10/28 | C25: 2025/10/31 | D25: 3 | E25: =D25*J25 -> 12 | F25: Agoda | G25: 43.10平米202室302室 | H25: 1 | I25: WEI-FENG CHI | J25: 4 | K25: 92793 | L25: 11136 | M25: 0 | N25: =SUM(O4:O25) -> 1607562 | O25: =K25-L25-M25 -> 81657 | P25: 0 | Q25: 事前決済
B26: 2025/09/29 | C26: 2025/10/01 | D26: 2 | E26: =D26*J26 -> 4 | F26: Airbnb | G26: 29.90平米101室201室301室 | H26: 1 | I26: Anastasia Androulidaki | J26: 2 | K26: 33360 | L26: 5004 | M26: 0 | O26: =K26-L26-M26 -> 28356 | P26: 0 | Q26: 事前決済
B27: 2025/09/27 | C27: 2025/10/04 | D27: 7 | E27: =D27*J27 -> 21 | F27: Airbnb | G27: 43.10平米202室302室 | H27: 1 | I27: Grace Wu | J27: 3 | K27: 186160 | L27: 27924 | M27: 0 | O27: =K27-L27-M27 -> 158236 | P27: 0 | Q27: 事前決済
B28: 2025/10/01 | C28: 2025/10/05 | D28: 4 | E28: =D28*J28 -> 8 | F28: Airbnb | G28: 29.90平米101室201室301室 | H28: 1 | I28: 冬冬吴 | J28: 2 | K28: 77840 | L28: 11676 | M28: 0 | O28: =K28-L28-M28 -> 66164 | P28: 0 | Q28: 事前決済
B29: 2025/10/05 | C29: 2025/10/07 | D29: 2 | E29: =D29*J29 -> 8 | F29: Airbnb | G29: 60.22平米401室 | H29: 1 | I29: Sarah Joe | J29: 4 | K29: 85000 | L29: 12750 | M29: 0 | O29: =K29-L29-M29 -> 72250 | P29: 0 | Q29: 事前決済
B30: 2025/10/04 | C30: 2025/10/07 | D30: 3 | E30: =D30*J30 -> 12 | F30: Airbnb | G30: 43.10平米202室302室 | H30: 1 | I30: Mel Westerhoff | J30: 4 | K30: 136140 | L30: 20421 | M30: 0 | O30: =K30-L30-M30 -> 115719 | P30: 0 | Q30: 事前決済
B31: 2025/10/02 | C31: 2025/10/07 | D31: 5 | E31: =D31*J31 -> 15 | F31: Airbnb | G31: 29.90平米101室201室301室 | H31: 1 | I31: 진욱 안 | J31: 3 | K31: 127880 | L31: 19182 | M31: 0 | O31: =K31-L31-M31 -> 108698 | P31: 0 | Q31: 事前決済
B32: 2025/10/08 | C32: 2025/10/12 | D32: 4 | E32: =D32*J32 -> 12 | F32: Airbnb | G32: 29.90平米101室201室301室 | H32: 1 | I32: 혜림 이 | J32: 3 | K32: 135640 | L32: 20346 | M32: 0 | O32: =K32-L32-M32 -> 115294 | P32: 0 | Q32: 事前決済
B33: 2025/10/10 | C33: 2025/10/12 | D33: 2 | E33: =D33*J33 -> 2 | F33: Airbnb | G33: 29.90平米101室201室301室 | H33: 1 | I33: Biela Elias | J33: 1 | K33: 61600 | L33: 9240 | M33: 0 | O33: =K33-L33-M33 -> 52360 | P33: 0 | Q33: 事前決済
B34: 2025/10/14 | C34: 2025/10/16 | D34: 2 | E34: =D34*J34 -> 6 | F34: Airbnb | G34: 43.10平米202室302室 | H34: 1 | I34: Winter Ku | J34: 3 | K34: 41800 | L34: 6270 | M34: 0 | O34: =K34-L34-M34 -> 35530 | P34: 0 | Q34: 事前決済
B35: 2025/10/05 | C35: 2025/10/16 | D35: 11 | E35: =D35*J35 -> 33 | F35: Airbnb | G35: 43.10平米202室302室 | H35: 1 | I35: Mike Lindensmith | J35: 3 | K35: 426020 | L35: 63903 | M35: 0 | O35: =K35-L35-M35 -> 362117 | P35: 0 | Q35: 事前決済
B36: 2025/10/17 | C36: 2025/10/19 | D36: 2 | E36: =D36*J36 -> 4 | F36: Airbnb | G36: 29.90平米101室201室301室 | H36: 1 | I36: Ki Ki | J36: 2 | K36: 50480 | L36: 7572 | M36: 0 | O36: =K36-L36-M36 -> 42908 | P36: 0 | Q36: 事前決済
B37: 2025/10/21 | C37: 2025/10/23 | D37: 2 | E37: =D37*J37 -> 6 | F37: Airbnb | G37: 43.10平米202室302室 | H37: 1 | I37: Yancheng Shen | J37: 3 | K37: 41800 | L37: 6270 | M37: 0 | O37: =K37-L37-M37 -> 35530 | P37: 0 | Q37: 事前決済
... B43: 2025/10/26 | C43: 2025/10/29 | D43: 3 | E43: =D43*J43 -> 9 | F43: Airbnb | G43: 43.10平米202室302室 | H43: 1 | I43: 서영 성 | J43: 3 | K43: 59700 | L43: 8955 | M43: 0 | O43: =K43-L43-M43 -> 50745 | P43: 0 | Q43: 事前決済
B44: 2025/10/28 | C44: 2025/10/31 | D44: 3 | E44: =D44*J44 -> 12 | F44: Airbnb | G44: 60.22平米401室 | H44: 1 | I44: 勃然 王 | J44: 4 | K44: 66000 | L44: 9900 | M44: 0 | N44: =SUM(O26:O44) -> 1637491 | O44: =K44-L44-M44 -> 56100 | P44: 0 | Q44: 事前決済
B45: 2025/09/26 | C45: 2025/10/01 | D45: 5 | E45: =D45*J45 -> 10 | F45: Booking.com | G45: 36.70平米102室402室 | H45: 1 | I45: Medvidovi? Sanda | J45: 2 | K45: 143350 | L45: 17202 | M45: 3297 | O45: =K45-L45-M45 -> 122851 | P45: 0 | Q45: 事前決済
B46: 2025/10/02 | C46: 2025/10/08 | D46: 6 | E46: =D46*J46 -> 12 | F46: Booking.com | G46: 29.90平米101室201室301室 | H46: 1 | I46: Sanziana Enache | J46: 2 | K46: 180700 | L46: 21684 | M46: 4156 | O46: =K46-L46-M46 -> 154860 | P46: 0 | Q46: 事前決済
B47: 2025/10/04 | C47: 2025/10/08 | D47: 4 | E47: =D47*J47 -> 12 | F47: Booking.com | G47: 36.70平米102室402室 | H47: 1 | I47: KIM YONGSEOK | J47: 3 | K47: 98208 | L47: 11785 | M47: 2259 | O47: =K47-L47-M47 -> 84164 | P47: 0 | Q47: 事前決済
B48: 2025/10/09 | C48: 2025/10/14 | D48: 5 | E48: =D48*J48 -> 20 | F48: Booking.com | G48: 43.10平米202室302室 | H48: 1 | I48: Kayley Tan | J48: 4 | K48: 200124 | L48: 24015 | M48: 4603 | O48: =K48-L48-M48 -> 171506 | P48: 0 | Q48: 事前決済
B49: 2025/10/12 | C49: 2025/10/15 | D49: 3 | E49: =D49*J49 -> 6 | F49: Booking.com | G49: 36.70平米102室402室 | H49: 1 | I49: Jeffrey Bartlett | J49: 2 | K49: 67000 | L49: 8040 | M49: 1541 | O49: =K49-L49-M49 -> 57419 | P49: 0 | Q49: 事前決済
B50: 2025/10/13 | C50: 2025/10/18 | D50: 5 | E50: =D50*J50 -> 15 | F50: Booking.com | G50: 46.64平米403室 | H50: 1 | I50: Adi Shani | J50: 3 | K50: 161190 | L50: 19343 | M50: 3707 | O50: =K50-L50-M50 -> 138140 | P50: 0 | Q50: 事前決済
B51: 2025/10/17 | C51: 2025/10/19 | D51: 2 | E51: =D51*J51 -> 4 | F51: Booking.com | G51: 29.90平米101室201室301室 | H51: 1 | I51: Bethany Sapp | J51: 2 | K51: 44480 | L51: 5338 | M51: 1023 | O51: =K51-L51-M51 -> 38119 | P51: 0 | Q51: 事前決済
B52: 2025/10/16 | C52: 2025/10/20 | D52: 4 | E52: =D52*J52 -> 8 | F52: Booking.com | G52: 29.90平米101室201室301室 | H52: 1 | I52: Tang George | J52: 2 | K52: 122760 | L52: 14731 | M52: 2823 | O52: =K52-L52-M52 -> 105206 | P52: 0 | Q52: 事前決済
B53: 2025/10/17 | C53: 2025/10/22 | D53: 5 | E53: =D53*J53 -> 5 | F53: Booking.com | G53: 43.10平米202室302室 | H53: 1 | I53: Jon Warner | J53: 1 | K53: 185007 | L53: 22201 | M53: 4255 | O53: =K53-L53-M53 -> 158551 | P53: 0 | Q53: 事前決済
B54: 2025/10/24 | C54: 2025/10/26 | D54: 2 | E54: =D54*J54 -> 2 | F54: Booking.com | G54: 36.70平米102室402室 | H54: 1 | I54: Артем Раков | J54: 1 | K54: 61000 | L54: 7320 | M54: 1403 | N54: =SUM(O45:O54) -> 1083093 | O54: =K54-L54-M54 -> 52277 | P54: 0 | Q54: 事前決済
...

Sheet 2025年10月分析データ表
B2: ホテル運営分析データ表 | J2: 部屋番号 | K2: 客室タイプごとの平均宿泊人数（1泊あたり） | L2: 客室数 | M2: 面積（㎡） | O2: 総売上（円） | P2: 客室タイプごとの稼働率 | Q2: 実販売室泊（室泊） | R2: 宿泊延べ日数（人泊）※ | S2: 販売可能室泊（室泊） | T2: ADR（平均客室単価） | U2: 人数単価（人均単価：1人あたり） | V2: RevPAR（1室当たり収益） | W2: ㎡単価（日額）＝「1㎡あたり1日」
B3: ① 物件基本情報 | E3: ③ 客源平台（チャネル別） | J3: 101 | K3: =R3/Q3 -> #DIV/0! | L3: 3 | M3: 29.9 | N3: =L3*M3 -> 89.7 | O3: 1932862 | P3: =Q3/(L3*C22)*100% -> 0 | R3: 54 | S3: =L3*C22 -> 93 | T3: =O3/Q3 -> #DIV/0! | U3: =O3/R3 -> 35793.741 | V3: =O3/S3 -> 20783.462 | W3: =IFERROR(O3/(N3*C22),0) -> 695.09908
B4: A（項目） | C4: B（値） | E4: D（チャネル） | F4: E（売上） | G4: F（予約件数） | H4: G（売上構成比） | J4: 201
B5: 分析開始日（チェクアウト日基準） | C5: 45931 | E5: Airbnb | F5: 1926460 | G5: 19 | H5: =IFERROR(F5/$F$13,0) -> 0.28593722 | J5: 301
B6: 分析終了日（チェクアウト日基準） | C6: 45961 | E6: Booking.com | F6: 1263819 | G6: 10 | H6: =IFERROR(F6/$F$13,0) -> 0.18758391 | J6: 102 | K6: =R6/Q6 -> #DIV/0! | L6: 2 | M6: 36.7 | N6: =L6*M6 -> 73.4 | O6: 1324310 | P6: =Q6/S6*100% -> 0 | R6: 30 | S6: =L6*C22 -> 62 | T6: =O6/Q6 -> #DIV/0! | U6: =O6/R6 -> 44143.667 | V6: =O6/S6 -> 21359.839 | W6: =IFERROR(O6/(N6*C22),0) -> 582.01195
B7: 延床面積（㎡） | C7: 356 | E7: Agoda | F7: 1826777 | G7: 22 | H7: =IFERROR(F7/$F$13,0) -> 0.27114165 | J7: 402
B8: 客室数 | C8: 9 | E8: Expedia | F8: 234387 | G8: 3 | H8: =IFERROR(F8/$F$13,0) -> 0.034789182 | J8: 202 | K8: =R8/Q8 -> #DIV/0! | L8: 2 | M8: 43.1 | N8: =L8*M8 -> 86.2 | O8: 2003479 | P8: =Q8/S8*100% -> 0 | R8: 52 | S8: =L8*C22 -> 62 | T8: =O8/Q8 -> #DIV/0! | U8: =O8/R8 -> 38528.442 | V8: =O8/S8 -> 32314.177 | W8: =IFERROR(O8/(N8*C22),0) -> 749.7489
B9: 総売上（円） | C9: =[1]予約明細!P1 -> 6737353 | E9: Trip.com | F9: 1485910 | G9: 19 | H9: =IFERROR(F9/$F$13,0) -> 0.22054804 | J9: 302
B10: 総宿泊人数（人） | C10: ='2025年10月予約一覧表'!J2 -> 186 | E10: じゃらん | F10: 0 | G10: 0 | H10: =IFERROR(F10/$F$13,0) -> 0 | J10: 403 | K10: =R10/Q10 -> #DIV/0! | L10: 1 | M10: 46.64 | O10: 796702 | P10: =Q10/S10*100% -> 0 | R10: 23 | S10: =L10*C22 -> 31 | T10: =O10/Q10 -> #DIV/0! | U10: =O10/R10 -> 34639.217 | V10: =O10/S10 -> 25700.065 | W10: =IFERROR(O10/(M10*C22),0) -> 551.03054
B11: 宿泊延べ日数（人泊）※ | C11: ='2025年10月予約一覧表'!E2 -> 609 | E11: 一休.com | F11: 0 | G11: 0 | H11: =IFERROR(F11/$F$13,0) -> 0 | J11: 401 | K11: =R11/Q11 -> #DIV/0! | L11: 1 | M11: 60.22 | O11: 680000 | P11: =Q11/S11*100% -> 0 | R11: 27 | S11: =L11*C22 -> 31 | T11: =O11/Q11 -> #DIV/0! | U11: =O11/R11 -> 25185.185 | V11: =O11/S11 -> 21935.484 | W11: =IFERROR(O11/(M11*C22),0) -> 364.25579
B12: 販売可能室数（室） | C12: 9 | E12: 自社 | F12: 0 | G12: 0 | H12: =IFERROR(F12/$F$13,0) -> 0 | L12: =SUM(L3:L11) -> 9 | M12: =(M3*L3)+(L6*M6)+(L8*M8)+M10+M11 -> 356.16 | O12: =SUM(O3:O11) -> 6737353 | Q12: =SUM(Q3:Q11) -> 0 | R12: =SUM(R3:R11) -> 186 | S12: =SUM(S3:S11) -> 279
B13: 販売可能室泊（室泊） | C13: =C8*C22 -> 279 | E13: 合計 | F13: =SUM(F5:F12) -> 6737353 | G13: =SUM(G5:G12) -> 73 | H13: =IFERROR(F13/$F$13,0) -> 1
B14: 実販売室泊（室泊） | C14: ='2025年10月予約一覧表'!D2 -> 239
B15: キャンセル件数（件）
B16: 予約総件数（件） | C16: ='2025年10月予約一覧表'!H2 -> 73
B17: キャンセル室泊（室泊）
B18: ※「宿泊延べ日数（人泊）」＝各予約の「人数×泊数」の合計（人泊）。
B19: 「実販売室泊（室泊）」＝各予約の「室数×泊数」の合計（室泊）。
B21: ② 計算（自動）
B22: 期間日数（日数） | C22: =DATEDIF(C5,C6,"D")+1 -> 31
B23: 稼働率（OCC） | C23: =IFERROR(C14/C13,0) -> 0.85663082
B24: ADR（平均客室単価） | C24: =IFERROR(C9/C14,0) -> 28189.762
B25: 人数単価（人均単価：1人あたり） | C25: =IFERROR(C9/C11,0) -> 11062.977
B26: RevPAR（1室当たり収益） | C26: =IFERROR(C9/C13,0) -> 24148.219
B27: ㎡単価（日額）＝「1㎡あたり1日」 | C27: =IFERROR(C9/(C7*C22),0) -> 610.48867
B28: 取消率（件数ベース） | C28: =IFERROR(C15/C16,0) -> 0
B29: 取消稼働率（室泊ベース） | C29: =IFERROR(C17/(C14+C17),0) -> 0

Sheet 2025年11月予約一覧表
D2: =SUM(D4:D322) -> 251 | E2: =SUM(E4:E322) -> 634 | H2: =SUM(H4:H322) -> 83 | J2: =SUM(J4:J322) -> 208 | K2: =SUM(K4:K322) -> 7079337 | L2: =SUM(L4:L322) -> 808071 | M2: =SUM(M4:M322) -> 36967 | N2: =SUM(N4:N322) -> 6234299 | O2: =SUM(O4:O322) -> 0
B3: チェックイン日 | C3: チェックアウト日 | D3: 泊数 | E3: 宿泊延べ日数 | F3: 予約サイト名称 | G3: 部屋タイプ名称 | H3: 室数 | I3: 宿泊者氏名 | J3: 大人人数計 | K3: 予約合計額 | L3: サービス料 | M3: クレジットカード手数料 | N3: 銀行入金小計 | O3: ポイント額 | P3: 決済方法
B4: 45957 | C4: 45962 | D4: 5 | E4: =D4*J4 -> 5 | F4: Agoda | G4: 29.90平米101室201室301室 | H4: 1 | I4: Kuah Zi Yuan Javier | J4: 1 | K4: 72555 | L4: 0 | M4: 0 | N4: =K4-L4-M4 -> 72555 | P4: 事前決済
B5: 45961 | C5: 45963 | D5: 2 | E5: =D5*J5 -> 4 | F5: Agoda | G5: 43.10平米202室302室 | H5: 1 | I5: Hwayoung Kim | J5: 2 | K5: 89078 | L5: 0 | M5: 0 | N5: =K5-L5-M5 -> 89078 | P5: 事前決済
B6: 45959 | C6: 45963 | D6: 4 | E6: =D6*J6 -> 4 | F6: Agoda | G6: 46.64平米403室 | H6: 1 | I6: EUNYOUNG LEE | J6: 1 | K6: 130922 | L6: 0 | M6: 0 | N6: =K6-L6-M6 -> 130922 | P6: 事前決済
B7: 45960 | C7: 45964 | D7: 4 | E7: =D7*J7 -> 8 | F7: Agoda | G7: 29.90平米101室201室301室 | H7: 1 | I7: Julian Chit Hei Ng | J7: 2 | K7: 83668 | L7: 0 | M7: 0 | N7: =K7-L7-M7 -> 83668 | P7: 事前決済
B8: 45964 | C8: 45967 | D8: 3 | E8: =D8*J8 -> 6 | F8: Agoda | G8: 43.10平米202室302室 | H8: 1 | I8: JOORANG YOON | J8: 2 | K8: 61986 | L8: 0 | M8: 0 | N8: =K8-L8-M8 -> 61986 | P8: 事前決済
B9: 45965 | C9: 45968 | D9: 3 | E9: =D9*J9 -> 9 | F9: Agoda | G9: 29.90平米101室201室301室 | H9: 1 | I9: Elysse Enriquez | J9: 3 | K9: 60874 | L9: 0 | M9: 0 | N9: =K9-L9-M9 -> 60874 | P9: 事前決済
B10: 45967 | C10: 45970 | D10: 3 | E10: =D10*J10 -> 9 | F10: Agoda | G10: 46.64平米403室 | H10: 1 | I10: SIU TING TSE | J10: 3 | K10: 89115 | L10: 0 | M10: 0 | N10: =K10-L10-M10 -> 89115 | P10: 事前決済
B11: 45975 | C11: 45977 | D11: 2 | E11: =D11*J11 -> 6 | F11: Agoda | G11: 43.10平米202室302室 | H11: 1 | I11: AYEON PARK | J11: 3 | K11: 49384 | L11: 0 | M11: 0 | N11: =K11-L11-M11 -> 49384 | P11: 事前決済
B12: 45978 | C12: 45980 | D12: 2 | E12: =D12*J12 -> 4 | F12: Agoda | G12: 36.70平米102室402室 | H12: 1 | I12: Fang yu Liu | J12: 2 | K12: 37488 | L12: 0 | M12: 0 | N12: =K12-L12-M12 -> 37488 | P12: 事前決済
B13: 45978 | C13: 45980 | D13: 2 | E13: =D13*J13 -> 4 | F13: Agoda | G13: 29.90平米101室201室301室 | H13: 1 | I13: Christian Winata | J13: 2 | K13: 44036 | L13: 0 | M13: 0 | N13: =K13-L13-M13 -> 44036 | P13: 事前決済
B14: 45974 | C14: 45981 | D14: 7 | E14: =D14*J14 -> 14 | F14: Agoda | G14: 29.90平米101室201室301室 | H14: 1 | I14: Samuel Tieu | J14: 2 | K14: 183866 | L14: 0 | M14: 0 | N14: =K14-L14-M14 -> 183866 | P14: 事前決済
B15: 45982 | C15: 45984 | D15: 2 | E15: =D15*J15 -> 4 | F15: Agoda | G15: 29.90平米101室201室301室 | H15: 1 | I15: MISATO MOTOKI | J15: 2 | K15: 44422 | L15: 0 | M15: 0 | N15: =K15-L15-M15 -> 44422 | P15: 事前決済
... B80: 45989 | C80: 45991 | D80: 2 | E80: =D80*J80 -> 6 | F80: Trip.com | G80: 36.70平米102室402室 | H80: 1 | I80: FANG JEAN EU | J80: 3 | K80: 79100 | L80: 9492 | M80: 0 | N80: =K80-L80-M80 -> 69608 | P80: 事前決済
B81: 45988 | C81: 45989 | D81: 1 | E81: =D81*J81 -> 1 | F81: 一休.com | G81: 43.10平米202室302室 | H81: 1 | I81: 原田 央 | J81: 1 | K81: 15250 | L81: 12568 | M81: 4398 | N81: 97298 | P81: 事前決済
B82: 45988 | C82: 45989 | D82: 1 | E82: =D82*J82 -> 2 | F82: 一休.com | G82: 46.64平米403室 | H82: 1 | I82: 河村 潤一郎 | J82: 2 | K82: 15250 | P82: 事前決済
B83: 45990 | C83: 45991 | D83: 1 | E83: =D83*J83 -> 2 | F83: 一休.com | G83: 29.90平米101室201室301室 | H83: 1 | I83: 岩田進一 | J83: 2 | K83: 22240 | P83: 事前決済
B84: 45980 | C84: 45982 | D84: 2 | E84: =D84*J84 -> 2 | F84: 一休.com | G84: 29.90平米101室201室301室 | H84: 1 | I84: 高橋 愛美 | J84: 1 | K84: 30580 | P84: 事前決済
B85: 45985 | C85: 45986 | D85: 1 | E85: =D85*J85 -> 3 | F85: 一休.com | G85: 46.64平米403室 | H85: 1 | I85: 粂川 慶一 | J85: 3 | K85: 19824 | P85: 事前決済
B86: 45973 | C86: 45974 | D86: 1 | E86: =D86*J86 -> 1 | F86: 一休.com | G86: 29.90平米101室201室301室 | H86: 1 | I86: 本多 宗来 | J86: 1 | K86: 11120 | P86: 事前決済

Sheet 2025年11月分析データ表
B2: ホテル運営分析データ表 | J2: 部屋番号 | K2: 客室タイプごとの平均宿泊人数（1泊あたり） | L2: 客室数 | M2: 面積（㎡） | O2: 総売上（円） | P2: 客室タイプごとの稼働率 | Q2: 実販売室泊（室泊） | R2: 宿泊延べ日数（人泊）※ | S2: 販売可能室泊（室泊） | T2: ADR（平均客室単価） | U2: 人数単価（人均単価：1人あたり） | V2: RevPAR（1室当たり収益） | W2: ㎡単価（日額）＝「1㎡あたり1日」
B3: ① 物件基本情報 | E3: ③ 客源平台（チャネル別） | J3: 101 | K3: =R3/Q3 -> 1.9767442 | L3: 3 | M3: 29.9 | N3: =L3*M3 -> 89.7 | O3: 1907552 | P3: =Q3/(L3*C22)*100% -> 0.95555556 | Q3: 86 | R3: 170 | S3: =L3*C22 -> 90 | T3: =O3/Q3 -> 22180.837 | U3: =O3/R3 -> 11220.894 | V3: =O3/S3 -> 21195.022 | W3: =IFERROR(O3/(N3*C22),0) -> 708.86362
B4: A（項目） | C4: B（値） | E4: D（チャネル） | F4: E（売上） | G4: F（予約件数） | H4: G（売上構成比） | J4: 201
B5: 分析開始日（チェクアウト日基準） | C5: 45962 | E5: Airbnb | F5: 1609290 | G5: 15 | H5: =IFERROR(F5/$F$13,0) -> 0.22732213 | J5: 301
B6: 分析終了日（チェクアウト日基準） | C6: 45991 | E6: Booking.com | F6: 1415977 | G6: 20 | H6: =IFERROR(F6/$F$13,0) -> 0.20001548 | J6: 102 | K6: =R6/Q6 -> 2.295082 | L6: 2 | M6: 36.7 | N6: =L6*M6 -> 73.4 | O6: 1613229 | P6: =Q6/S6*100% -> 1.0166667 | Q6: 61 | R6: 140 | S6: =L6*C22 -> 60 | T6: =O6/Q6 -> 26446.377 | U6: =O6/R6 -> 11523.064 | V6: =O6/S6 -> 26887.15 | W6: =IFERROR(O6/(N6*C22),0) -> 732.61989
B7: 延床面積（㎡） | C7: 356 | E7: Agoda | F7: 1386279 | G7: 18 | H7: =IFERROR(F7/$F$13,0) -> 0.19582046 | J7: 402
B8: 客室数 | C8: 9 | E8: Expedia | F8: 1364207 | G8: 8 | H8: =IFERROR(F8/$F$13,0) -> 0.19270265 | J8: 202 | K8: =R8/Q8 -> 2.8135593 | L8: 2 | M8: 43.1 | N8: =L8*M8 -> 86.2 | O8: 1769059 | P8: =Q8/S8*100% -> 0.98333333 | Q8: 59 | R8: 166 | S8: =L8*C22 -> 60 | T8: =O8/Q8 -> 29984.051 | U8: =O8/R8 -> 10656.982 | V8: =O8/S8 -> 29484.317 | W8: =IFERROR(O8/(N8*C22),0) -> 684.09087
B9: 総売上（円） | C9: ='2025年11月予約一覧表'!K2 -> 7079337 | E9: Trip.com | F9: 1189320 | G9: 16 | H9: =IFERROR(F9/$F$13,0) -> 0.16799878 | J9: 302
B10: 総宿泊人数（人） | C10: ='2025年11月予約一覧表'!J2 -> 208 | E10: じゃらん | F10: 0 | G10: 0 | H10: =IFERROR(F10/$F$13,0) -> 0 | J10: 403 | K10: =R10/Q10 -> 3.0357143 | L10: 1 | M10: 46.64 | O10: 897847 | P10: =Q10/S10*100% -> 0.93333333 | Q10: 28 | R10: 85 | S10: =L10*C22 -> 30 | T10: =O10/Q10 -> 32065.964 | U10: =O10/R10 -> 10562.906 | V10: =O10/S10 -> 29928.233 | W10: =IFERROR(O10/(M10*C22),0) -> 641.68596
B11: 宿泊延べ日数（人泊）※ | C11: ='2025年11月予約一覧表'!E2 -> 634 | E11: 一休.com | F11: 114264 | G11: 6 | H11: =IFERROR(F11/$F$13,0) -> 0.016140495 | J11: 401 | K11: =R11/Q11 -> 4.1176471 | L11: 1 | M11: 60.22 | O11: 891650 | P11: =Q11/S11*100% -> 0.56666667 | Q11: 17 | R11: 70 | S11: =L11*C22 -> 30 | T11: =O11/Q11 -> 52450 | U11: =O11/R11 -> 12737.857 | V11: =O11/S11 -> 29721.667 | W11: =IFERROR(O11/(M11*C22),0) -> 493.55142
B12: 販売可能室数（室） | C12: 9 | E12: 自社 | H12: =IFERROR(F12/$F$13,0) -> 0 | L12: =SUM(L3:L11) -> 9 | M12: =(M3*L3)+(L6*M6)+(L8*M8)+M10+M11 -> 356.16 | O12: =SUM(O3:O11) -> 7079337 | Q12: =SUM(Q3:Q11) -> 251 | R12: =SUM(R3:R11) -> 631 | S12: =SUM(S3:S11) -> 270
B13: 販売可能室泊（室泊） | C13: =C8*C22 -> 270 | E13: 合計 | F13: =SUM(F5:F12) -> 7079337 | G13: =SUM(G5:G12) -> 83 | H13: =IFERROR(F13/$F$13,0) -> 1
B14: 実販売室泊（室泊） | C14: ='2025年11月予約一覧表'!D2 -> 251
B15: キャンセル件数（件） | C15: 39
B16: 予約総件数（件） | C16: ='2025年11月予約一覧表'!H2 -> 83
B17: キャンセル室泊（室泊）
B18: ※「宿泊延べ日数（人泊）」＝各予約の「人数×泊数」の合計（人泊）。
B19: 「実販売室泊（室泊）」＝各予約の「室数×泊数」の合計（室泊）。
B21: ② 計算（自動）
B22: 期間日数（日数） | C22: =DATEDIF(C5,C6,"D")+1 -> 30
B23: 稼働率（OCC） | C23: =IFERROR(C14/C13,0) -> 0.92962963
B24: ADR（平均客室単価） | C24: =IFERROR(C9/C14,0) -> 28204.53
B25: 人数単価（人均単価：1人あたり） | C25: =IFERROR(C9/C11,0) -> 11166.147
B26: RevPAR（1室当たり収益） | C26: =IFERROR(C9/C13,0) -> 26219.767
B27: ㎡単価（日額）＝「1㎡あたり1日」 | C27: =IFERROR(C9/(C7*C22),0) -> 662.85927
B28: 取消率（件数ベース） | C28: =IFERROR(C15/C16,0) -> 0.46987952
B29: 取消稼働率（室泊ベース） | C29: =IFERROR(C17/(C14+C17),0) -> 0

Sheet 2025年12月予約一覧表
D2: =SUM(D4:D88) -> 248 | E2: =SUM(E4:E88) -> 654 | H2: =SUM(H4:H88) -> 84 | J2: =SUM(J4:J88) -> 221 | K2: =SUM(K4:K88) -> 7256184 | L2: =SUM(L4:L88) -> 850590 | M2: =SUM(M4:M88) -> 31981 | N2: =SUM(N4:N88) -> 5541554 | O2: =SUM(O4:O88) -> 3059
B3: チェックイン日 | C3: チェックアウト日 | D3: 泊数 | E3: 宿泊延べ日数 | F3: 予約サイト名称 | G3: 部屋タイプ名称 | H3: 室数 | I3: 宿泊者氏名 | J3: 大人人数計 | K3: 予約合計額 | L3: サービス料 | M3: クレジットカード手数料 | N3: サイド別銀行入金小計 | O3: ポイント割引額 | P3: 決済方法
B4: 45992 | C4: 45996 | D4: 4 | E4: =D4*J4 -> 8 | F4: Agoda | G4: 29.90平米101室201室301室 | H4: 1 | I4: warut ruksuuthee | J4: 2 | K4: 86620 | L4: 10394 | M4: 0 | N4: =K4-L4-M4 -> 76226 | O4: 0 | P4: 事前決済
B5: 45993 | C5: 45996 | D5: 3 | E5: =D5*J5 -> 6 | F5: Agoda | G5: 46.64平米403室 | H5: 1 | I5: hyuna kim | J5: 2 | K5: 75840 | L5: 9102 | M5: 0 | N5: =K5-L5-M5 -> 66738 | O5: 0 | P5: 事前決済
B6: 45993 | C6: 45995 | D6: 2 | E6: =D6*J6 -> 4 | F6: Agoda | G6: 43.10平米202室302室 | H6: 1 | I6: HYUJONG KANG | J6: 2 | K6: 63280 | L6: 7594 | M6: 0 | N6: =K6-L6-M6 -> 55686 | O6: 0 | P6: 事前決済
B7: 45997 | C7: 46000 | D7: 3 | E7: =D7*J7 -> 9 | F7: Agoda | G7: 46.64平米403室 | H7: 1 | I7: ShengNeng Wei | J7: 3 | K7: 99114 | L7: 11895 | M7: 0 | N7: =K7-L7-M7 -> 87219 | O7: 0 | P7: 事前決済
B8: 45997 | C8: 45999 | D8: 2 | E8: =D8*J8 -> 6 | F8: Agoda | G8: 29.90平米101室201室301室 | H8: 1 | I8: Alison Tan | J8: 3 | K8: 63756 | L8: 7650 | M8: 0 | N8: =K8-L8-M8 -> 56106 | O8: 0 | P8: 事前決済
B9: 46000 | C9: 46003 | D9: 3 | E9: =D9*J9 -> 6 | F9: Agoda | G9: 29.90平米101室201室301室 | H9: 1 | I9: JuChen Lin | J9: 2 | K9: 44920 | L9: 5390 | M9: 0 | N9: =K9-L9-M9 -> 39530 | O9: 0 | P9: 事前決済
B10: 46000 | C10: 46004 | D10: 4 | E10: =D10*J10 -> 4 | F10: Agoda | G10: 36.70平米102室402室 | H10: 1 | I10: Heeju Kim | J10: 1 | K10: 85300 | L10: 10236 | M10: 0 | N10: =K10-L10-M10 -> 75064 | O10: 0 | P10: 事前決済
B11: 46000 | C11: 46003 | D11: 3 | E11: =D11*J11 -> 9 | F11: Agoda | G11: 36.70平米102室402室 | H11: 1 | I11: HSIAO HSUAN CHIEN | J11: 3 | K11: 81327 | L11: 9758 | M11: 0 | N11: =K11-L11-M11 -> 71569 | O11: 0 | P11: 事前決済
B12: 46001 | C12: 46004 | D12: 3 | E12: =D12*J12 -> 9 | F12: Agoda | G12: 46.64平米403室 | H12: 1 | I12: SEONG SEOK MUN | J12: 3 | K12: 99114 | L12: 11895 | M12: 0 | N12: =K12-L12-M12 -> 87219 | O12: 0 | P12: 事前決済
B13: 46002 | C13: 46005 | D13: 3 | E13: =D13*J13 -> 6 | F13: Agoda | G13: 29.90平米101室201室301室 | H13: 1 | I13: Ki jeong Yun | J13: 2 | K13: 86620 | L13: 10394 | M13: 0 | N13: =K13-L13-M13 -> 76226 | O13: 0 | P13: 事前決済
B14: 46002 | C14: 46004 | D14: 2 | E14: =D14*J14 -> 4 | F14: Agoda | G14: 43.10平米202室302室 | H14: 1 | I14: Chee Hou Lai | J14: 2 | K14: 73462 | L14: 8816 | M14: 0 | N14: =K14-L14-M14 -> 64646 | O14: 0 | P14: 事前決済
B15: 46003 | C15: 46007 | D15: 4 | E15: =D15*J15 -> 16 | F15: Agoda | G15: 60.22平米401室 | H15: 1 | I15: chialin chuang | J15: 4 | K15: 166000 | L15: 19920 | M15: 0 | N15: =K15-L15-M15 -> 146080 | O15: 0 | P15: 事前決済
... B67: 46010 | C67: 46014 | D67: 4 | E67: =D67*J67 -> 16 | F67: Trip.com | G67: 46.64平米403室 | H67: 1 | I67: CHIEHCHIA CHEN | J67: 4 | K67: 183080 | L67: 21970 | M67: 0 | N67: =K67-L67-M67 -> 161110 | O67: 0 | P67: 事前決済
B68: 46004 | C68: 46005 | D68: 1 | E68: =D68*J68 -> 2 | F68: 一休.com | G68: 36.70平米102室402室 | H68: 1 | I68: 西村 信哉 | J68: 2 | K68: 21350 | L68: 11819 | M68: =3771+364 -> 4135 | N68: 89281 | O68: 2215 | P68: 事前決済
B69: 46010 | C69: 46011 | D69: 1 | E69: =D69*J69 -> 2 | F69: 一休.com | G69: 29.90平米101室201室301室 | H69: 1 | I69: 佐々木 博子 | J69: 2 | K69: 11120 | P69: 事前決済
B70: 46011 | C70: 46012 | D70: 1 | E70: =D70*J70 -> 2 | F70: 一休.com | G70: 60.22平米401室 | H70: 1 | I70: 出村 幸世 | J70: 2 | K70: 12200 | P70: 事前決済
B71: 46014 | C71: 46015 | D71: 1 | E71: =D71*J71 -> 2 | F71: 一休.com | G71: 29.90平米101室201室301室 | H71: 1 | I71: 幸次 樹璃 | J71: 2 | K71: 11120 | P71: 事前決済
B72: 46015 | C72: 46016 | D72: 1 | E72: =D72*J72 -> 2 | F72: 一休.com | G72: 36.70平米102室402室 | H72: 1 | I72: 水石 大樹 | J72: 2 | K72: 18300 | P72: 事前決済
B73: 46016 | C73: 46018 | D73: 2 | E73: =D73*J73 -> 4 | F73: 一休.com | G73: 29.90平米101室201室301室 | H73: 1 | I73: 江口優里奈 | J73: 2 | K73: 22240 | P73: 事前決済
B74: 46018 | C74: 46019 | D74: 1 | E74: =D74*J74 -> 2 | F74: 一休.com | G74: 29.90平米101室201室301室 | H74: 1 | I74: 松浦 利典 | J74: 2 | K74: 11120 | P74: 事前決済
B75: 46004 | C75: 46005 | D75: 1 | E75: =D75*J75 -> 3 | F75: じゃらんnet | G75: 43.10平米202室302室 | H75: 1 | I75: 下村 夢美 | J75: 3 | K75: 35682 | L75: 8361 | M75: 0 | N75: =K75-L75-O75 -> 26477 | O75: 844 | P75: 現金
B76: 46010 | C76: 46012 | D76: 2 | E76: =D76*J76 -> 4 | F76: じゃらんnet | G76: 36.70平米102室402室 | H76: 1 | I76: 橋本 公平 | J76: 2 | K76: 24400 | M76: 0 | N76: =K76 -> 24400 | P76: 現金
B77: 45991 | C77: 45993 | D77: 2 | E77: =D77*J77 -> 4 | F77: RED | G77: 36.70平米102室402室OFF | H77: 1 | I77: TH（カ | J77: 2 | K77: 52000 | P77: 事前決済
B78: 45991 | C78: 45995 | D78: 4 | E78: =D78*J78 -> 12 | F78: RED | G78: 43.10平米202室302室OFF | H78: 1 | I78: 杉原 | J78: 3 | K78: 144000 | P78: 事前決済
B79: 45995 | C79: 45997 | D79: 2 | E79: =D79*J79 -> 6 | F79: RED | G79: 43.10平米202室302室OFF | H79: 1 | I79: 金城 | J79: 3 | K79: 72000 | P79: 事前決済
B80: 45991 | C80: 45993 | D80: 2 | E80: =D80*J80 -> 8 | F80: RED | G80: 60.22平米401室OFF | H80: 1 | I80: LlN CHl | J80: 4 | K80: 104000 | P80: 事前決済
B81: 45998 | C81: 46000 | D81: 2 | E81: =D81*J81 -> 4 | F81: RED | G81: 29.90平米101室201室301室OFF | H81: 1 | I81: 王先生 | J81: 2 | K81: 50000 | P81: 事前決済
B82: 45999 | C82: 46002 | D82: 3 | E82: =D82*J82 -> 6 | F82: RED | G82: 43.10平米202室302室OFF | H82: 1 | I82: yun Hong | J82: 2 | K82: 72000 | P82: 事前決済
B83: 46000 | C83: 46003 | D83: 3 | E83: =D83*J83 -> 12 | F83: RED | G83: 60.22平米401室OFF | H83: 1 | I83: wang yan | J83: 4 | K83: 144000 | P83: 事前決済
B84: 46006 | C84: 46009 | D84: 3 | E84: =D84*J84 -> 6 | F84: 微信公众号 | G84: 36.70平米102室402室OFF | H84: 1 | I84: 舜日（song yan) | J84: 2 | K84: 78000 | P84: 事前決済
B85: 46014 | C85: 46015 | D85: 1 | E85: =D85*J85 -> 2 | F85: 康新线下 | G85: 36.70平米102室402室OFF | H85: 1 | J85: 2 | K85: 26000 | P85: 事前決済
B86: 46006 | C86: 46008 | D86: 2 | E86: =D86*J86 -> 4 | F86: 康新线下 | G86: 36.70平米102室402室OFF | H86: 1 | J86: 2 | K86: 48000 | P86: 事前決済
B87: 46014 | C87: 46015 | D87: 1 | E87: =D87*J87 -> 3 | F87: 微信公众号 | G87: 46.64平米403室OFF | H87: 1 | I87: 舜日（liu siyu） | J87: 3 | K87: 39000 | P87: 事前決済

Sheet 2025年12月分析データ表
B2: ホテル運営分析データ表 | J2: 部屋番号 | K2: 客室タイプごとの平均宿泊人数（1泊あたり） | L2: 客室数 | M2: 面積（㎡） | O2: 総売上（円） | P2: 客室タイプごとの稼働率 | Q2: 実販売室泊（室泊） | R2: 宿泊延べ日数（人泊）※ | S2: 販売可能室泊（室泊） | T2: ADR（平均客室単価） | U2: 人数単価（人均単価：1人あたり） | V2: RevPAR（1室当たり収益） | W2: ㎡単価（日額）＝「1㎡あたり1日」
B3: ① 物件基本情報 | E3: ③ 客源平台（チャネル別） | J3: 101 | K3: =R3/Q3 -> 2.0879121 | L3: 3 | M3: 29.9 | N3: =L3*M3 -> 89.7 | O3: 2376053 | P3: =Q3/(L3*C22)*100% -> 0.97849462 | Q3: 91 | R3: 190 | S3: =L3*C22 -> 93 | T3: =O3/Q3 -> 26110.473 | U3: =O3/R3 -> 12505.542 | V3: =O3/S3 -> 25548.957 | W3: =IFERROR(O3/(N3*C22),0) -> 854.48017
B4: A（項目） | C4: B（値） | E4: D（チャネル） | F4: E（売上） | G4: F（予約件数） | H4: G（売上構成比） | J4: 201
B5: 分析開始日（チェクアウト日基準） | C5: 45992 | E5: Airbnb | F5: 1185190 | G5: 14 | H5: =IFERROR(F5/$F$13,0) -> 0.16333516 | J5: 301
B6: 分析終了日（チェクアウト日基準） | C6: 46022 | E6: Booking.com | F6: 1210694 | G6: 14 | H6: =IFERROR(F6/$F$13,0) -> 0.16684996 | J6: 102 | K6: =R6/Q6 -> 2.2586207 | L6: 2 | M6: 36.7 | N6: =L6*M6 -> 73.4 | O6: 1598781 | P6: =Q6/S6*100% -> 0.93548387 | Q6: 58 | R6: 131 | S6: =L6*C22 -> 62 | T6: =O6/Q6 -> 27565.19 | U6: =O6/R6 -> 12204.435 | V6: =O6/S6 -> 25786.79 | W6: =IFERROR(O6/(N6*C22),0) -> 702.63734
B7: 延床面積（㎡） | C7: 356 | E7: Agoda | F7: 2622268 | G7: 23 | H7: =IFERROR(F7/$F$13,0) -> 0.36138389 | J7: 402
B8: 客室数 | C8: 9 | E8: Expedia | F8: 814710 | G8: 8 | H8: =IFERROR(F8/$F$13,0) -> 0.11227802 | J8: 202 | K8: =R8/Q8 -> 3.0612245 | L8: 2 | M8: 43.1 | N8: =L8*M8 -> 86.2 | O8: 1523483 | P8: =Q8/S8*100% -> 0.79032258 | Q8: 49 | R8: 150 | S8: =L8*C22 -> 62 | T8: =O8/Q8 -> 31091.49 | U8: =O8/R8 -> 10156.553 | V8: =O8/S8 -> 24572.306 | W8: =IFERROR(O8/(N8*C22),0) -> 570.12312
B9: 総売上（円） | C9: ='2025年12月予約一覧表'!K2 -> 7256184 | E9: Trip.com | F9: 426790 | G9: 5 | H9: =IFERROR(F9/$F$13,0) -> 0.058817417 | J9: 302
B10: 総宿泊人数（人） | C10: ='2025年12月予約一覧表'!J2 -> 221 | E10: じゃらん | F10: 60082 | G10: 2 | H10: =IFERROR(F10/$F$13,0) -> 0.0082801098 | J10: 403 | K10: =R10/Q10 -> 3.3478261 | L10: 1 | M10: 46.64 | O10: 786167 | P10: =Q10/S10*100% -> 0.74193548 | Q10: 23 | R10: 77 | S10: =L10*C22 -> 31 | T10: =O10/Q10 -> 34181.174 | U10: =O10/R10 -> 10209.961 | V10: =O10/S10 -> 25360.226 | W10: =IFERROR(O10/(M10*C22),0) -> 543.74412
B11: 宿泊延べ日数（人泊）※ | C11: ='2025年12月予約一覧表'!E2 -> 654 | E11: 一休.com | F11: 107450 | G11: 7 | H11: =IFERROR(F11/$F$13,0) -> 0.014808059 | J11: 401 | K11: =R11/Q11 -> 3.9259259 | L11: 1 | M11: 60.22 | O11: 971700 | P11: =Q11/S11*100% -> 0.87096774 | Q11: 27 | R11: 106 | S11: =L11*C22 -> 31 | T11: =O11/Q11 -> 35988.889 | U11: =O11/R11 -> 9166.9811 | V11: =O11/S11 -> 31345.161 | W11: =IFERROR(O11/(M11*C22),0) -> 520.51082
B12: 販売可能室数（室） | C12: 9 | E12: 自社 | F12: 829000 | G12: 11 | H12: =IFERROR(F12/$F$13,0) -> 0.11424738 | L12: =SUM(L3:L11) -> 9 | M12: =(M3*L3)+(L6*M6)+(L8*M8)+M10+M11 -> 356.16 | O12: =SUM(O3:O11) -> 7256184 | Q12: =SUM(Q3:Q11) -> 248 | R12: =SUM(R3:R11) -> 654 | S12: =SUM(S3:S11) -> 279
B13: 販売可能室泊（室泊） | C13: =C8*C22 -> 279 | E13: 合計 | F13: =SUM(F5:F12) -> 7256184 | G13: =SUM(G5:G12) -> 84 | H13: =IFERROR(F13/$F$13,0) -> 1
B14: 実販売室泊（室泊） | C14: ='2025年12月予約一覧表'!D2 -> 248
B15: キャンセル件数（件） | C15: 65
B16: 予約総件数（件） | C16: ='2025年12月予約一覧表'!H2 -> 84
B17: キャンセル室泊（室泊）
B18: ※「宿泊延べ日数（人泊）」＝各予約の「人数×泊数」の合計（人泊）。
B19: 「実販売室泊（室泊）」＝各予約の「室数×泊数」の合計（室泊）。
B21: ② 計算（自動）
B22: 期間日数（日数） | C22: =DATEDIF(C5,C6,"D")+1 -> 31
B23: 稼働率（OCC） | C23: =IFERROR(C14/C13,0) -> 0.88888889
B24: ADR（平均客室単価） | C24: =IFERROR(C9/C14,0) -> 29258.806
B25: 人数単価（人均単価：1人あたり） | C25: =IFERROR(C9/C11,0) -> 11095.083
B26: RevPAR（1室当たり収益） | C26: =IFERROR(C9/C13,0) -> 26007.828
B27: ㎡単価（日額）＝「1㎡あたり1日」 | C27: =IFERROR(C9/(C7*C22),0) -> 657.50127
B28: 取消率（件数ベース） | C28: =IFERROR(C15/C16,0) -> 0.77380952
B29: 取消稼働率（室泊ベース） | C29: =IFERROR(C17/(C14+C17),0) -> 0

Sheet 2026年１月予約一覧表
D2: =SUM(D4:D67) -> 0 | E2: =SUM(E4:E76) -> 224 | F2: =SUM(F4:F76) -> 635 | I2: =SUM(I4:I76) -> 68 | K2: =SUM(K4:K76) -> 187 | L2: =SUM(L4:L76) -> 6715278 | M2: =SUM(M4:M76) -> 817226 | N2: =SUM(N4:N76) -> 29086 | O2: =SUM(O4:O76) -> 5400321 | P2: =SUM(P4:P76) -> 3645
B3: チェックイン日 | C3: チェックアウト日 | D3: 申込日 | E3: 泊数 | F3: 宿泊延べ日数 | G3: 予約サイト名称 | H3: 部屋タイプ名称 | I3: 室数 | J3: 宿泊者氏名 | K3: 大人人数計 | L3: 予約合計額 | M3: サービス料 | N3: クレジットカード手数料 | O3: サイド別銀行入金小計 | P3: ポイント割引額 | Q3: 決済方法
